Workbook

Sheet Situacion Financiera
A1: COMPAÑÍA MINERA PODEROSA S.A.
A2: Estado Separado de Situación Financiera (al 31 de diciembre)
A3: Estados financieros separados (individuales) — Cifras en miles de soles (S/000) — NIIF
A5: Cuenta | B5: 2019 | C5: 2020 | D5: 2021 | E5: 2022 | F5: 2023 | G5: 2024 | H5: 2025
A6: ACTIVO
A7: Activo corriente
A8: Efectivo y equivalentes de efectivo | B8: 118831 | C8: 366089 | D8: 622048 | E8: 254238 | F8: 277363 | G8: 147809 | H8: 424335
A9: Otros activos financieros (depósitos > 90 días) | B9: 0 | C9: 0 | D9: 0 | E9: 171900 | F9: 0 | G9: 0 | H9: 0
A10: Cuentas por cobrar comerciales | B10: 9622 | C10: 12787 | D10: 10183 | E10: 12630 | F10: 14628 | G10: 19293 | H10: 34281
A11: Otras cuentas por cobrar | B11: 23718 | C11: 16688 | D11: 16592 | E11: 62109 | F11: 87810 | G11: 104314 | H11: 83432
A12: Inventarios | B12: 44353 | C12: 50084 | D12: 59856 | E12: 70544 | F12: 68270 | G12: 97619 | H12: 102859
A13: Gastos contratados por anticipado | B13: 16241 | C13: 19498 | D13: 13379 | E13: 14443 | F13: 16458 | G13: 13615 | H13: 11476
A14: Total activo corriente | B14: =SUM(B8:B13) -> 212765 | C14: =SUM(C8:C13) -> 465146 | D14: =SUM(D8:D13) -> 722058 | E14: =SUM(E8:E13) -> 585864 | F14: =SUM(F8:F13) -> 464529 | G14: =SUM(G8:G13) -> 382650 | H14: =SUM(H8:H13) -> 656383
A16: Activo no corriente
A17: Otras cuentas por cobrar (no corriente) | B17: 0 | C17: 0 | D17: 0 | E17: 5299 | F17: 5668 | G17: 5755 | H17: 5755
A18: Inversiones en subsidiarias y asociadas | B18: 25460 | C18: 25460 | D18: 25460 | E18: 25837 | F18: 25460 | G18: 25460 | H18: 25460
A19: Gastos contratados por anticipado (no corriente) | B19: 23291 | C19: 20411 | D19: 18580 | E19: 15013 | F19: 12011 | G19: 12011 | H19: 19095
A20: Propiedades, planta y equipo | B20: 555339 | C20: 668676 | D20: 761277 | E20: 829522 | F20: 1035860 | G20: 1106796 | H20: 1305460
A21: Activos por derecho de uso | B21: 40786 | C21: 21982 | D21: 30105 | E21: 29499 | F21: 21778 | G21: 17749 | H21: 13544
A22: Activos intangibles | B22: 532857 | C22: 506646 | D22: 514768 | E22: 609843 | F22: 762189 | G22: 992370 | H22: 1163147
A23: Total activo no corriente | B23: =SUM(B17:B22) -> 1177733 | C23: =SUM(C17:C22) -> 1243175 | D23: =SUM(D17:D22) -> 1350190 | E23: =SUM(E17:E22) -> 1515013 | F23: =SUM(F17:F22) -> 1862966 | G23: =SUM(G17:G22) -> 2160141 | H23: =SUM(H17:H22) -> 2532461
A25: TOTAL ACTIVO | B25: =B14+B23 -> 1390498 | C25: =C14+C23 -> 1708321 | D25: =D14+D23 -> 2072248 | E25: =E14+E23 -> 2100877 | F25: =F14+F23 -> 2327495 | G25: =G14+G23 -> 2542791 | H25: =H14+H23 -> 3188844
A28: PASIVO
A29: Pasivo corriente
A30: Cuentas por pagar comerciales | B30: 70981 | C30: 85609 | D30: 86042 | E30: 103394 | F30: 210432 | G30: 221961 | H30: 303688
A31: Otras cuentas por pagar | B31: 77351 | C31: 109926 | D31: 156479 | E31: 127512 | F31: 67911 | G31: 89451 | H31: 117990
A32: Pasivo por impuesto a las ganancias | B32: 0 | C32: 0 | D32: 0 | E32: 0 | F32: 0 | G32: 0 | H32: 62029
A33: Otros pasivos financieros | B33: 82525 | C33: 65650 | D33: 68532 | E33: 88270 | F33: 98735 | G33: 100100 | H33: 199052
A34: Pasivos por arrendamiento | B34: 15123 | C34: 10869 | D34: 11517 | E34: 5697 | F34: 4480 | G34: 1904 | H34: 1418
A35: Beneficios a los empleados | B35: 38013 | C35: 52331 | D35: 71526 | E35: 59491 | F35: 41236 | G35: 51276 | H35: 91718
A36: Provisiones | B36: 2548 | C36: 4014 | D36: 2283 | E36: 1575 | F36: 1765 | G36: 2470 | H36: 2472
A37: Instrumentos financieros derivados | B37: 2887 | C37: 6748 | D37: 0 | E37: 0 | F37: 0 | G37: 0 | H37: 0
A38: Parte corriente provisión cierre de minas / remediación | B38: 3109 | C38: 3397 | D38: 3748 | E38: 3581 | F38: 2923 | G38: 3392 | H38: 1836
A39: Total pasivo corriente | B39: =SUM(B30:B38) -> 292537 | C39: =SUM(C30:C38) -> 338544 | D39: =SUM(D30:D38) -> 400127 | E39: =SUM(E30:E38) -> 389520 | F39: =SUM(F30:F38) -> 427482 | G39: =SUM(G30:G38) -> 470554 | H39: =SUM(H30:H38) -> 780203
A41: Pasivo no corriente
A42: Otras cuentas por pagar (no corriente) | B42: 1177 | C42: 2659 | D42: 1660 | E42: 420 | F42: 241 | G42: 209 | H42: 174
A43: Otros pasivos financieros (no corriente) | B43: 47644 | C43: 43224 | D43: 31402 | E43: 0 | F43: 51982 | G43: 22620 | H43: 0
A44: Pasivos por arrendamiento (no corriente) | B44: 10749 | C44: 10954 | D44: 17220 | E44: 11751 | F44: 8761 | G44: 7441 | H44: 5194
A45: Provisión cierre de minas / remediación ambiental (no corriente) | B45: 26319 | C45: 74049 | D45: 67451 | E45: 61084 | F45: 128506 | G45: 62684 | H45: 129368
A46: Pasivo por impuestos diferidos | B46: 45163 | C46: 42513 | D46: 36468 | E46: 43120 | F46: 64913 | G46: 95761 | H46: 66926
...

Sheet Resultados
A1: COMPAÑÍA MINERA PODEROSA S.A.
A2: Estado Separado de Resultados y Otros Resultados Integrales (por el año terminado el 31 de diciembre)
A3: Estados financieros separados (individuales) — Cifras en miles de soles (S/000) — NIIF
A5: Cuenta | B5: 2019 | C5: 2020 | D5: 2021 | E5: 2022 | F5: 2023 | G5: 2024 | H5: 2025
A6: Ingresos de actividades ordinarias | B6: 1478809 | C6: 1663261 | D6: 2102747 | E6: 2090683 | F6: 1992610 | G6: 2624541 | H6: 3474265
A7: Costo de ventas | B7: -863491 | C7: -866319 | D7: -1101480 | E7: -1205403 | F7: -1324474 | G7: -1708130 | H7: -2104355
A8: Ganancia bruta | B8: =B6+B7 -> 615318 | C8: =C6+C7 -> 796942 | D8: =D6+D7 -> 1001267 | E8: =E6+E7 -> 885280 | F8: =F6+F7 -> 668136 | G8: =G6+G7 -> 916411 | H8: =H6+H7 -> 1369910
A10: Ingresos (gastos) de operación
A11: Gastos de venta | B11: -30659 | C11: -36080 | D11: -54900 | E11: -52160 | F11: -53764 | G11: -76754 | H11: -107225
A12: Gastos de administración | B12: -115644 | C12: -128472 | D12: -162202 | E12: -159221 | F12: -171810 | G12: -200960 | H12: -257099
A13: Otros ingresos | B13: 7329 | C13: 7962 | D13: 17768 | E13: 12917 | F13: 24406 | G13: 21860 | H13: 29686
A14: Otros gastos | B14: -1292 | C14: -4846 | D14: -1118 | E14: -53884 | F14: -10612 | G14: -8704 | H14: -1012
A15: Resultado de actividades de operación (utilidad operativa) | B15: =B8+B11+B12+B13+B14 -> 475052 | C15: =C8+C11+C12+C13+C14 -> 635506 | D15: =D8+D11+D12+D13+D14 -> 800815 | E15: =E8+E11+E12+E13+E14 -> 632932 | F15: =F8+F11+F12+F13+F14 -> 456356 | G15: =G8+G11+G12+G13+G14 -> 651853 | H15: =H8+H11+H12+H13+H14 -> 1034260
A17: Ingresos (gastos) financieros
A18: Ingresos financieros | B18: 1821 | C18: 1597 | D18: 7062 | E18: 18351 | F18: 10004 | G18: 6774 | H18: 7256
A19: Costos financieros | B19: -27479 | C19: -67901 | D19: -7910 | E19: -41060 | F19: -22136 | G19: -45309 | H19: -28098
A20: Costo financiero neto | B20: =B18+B19 -> -25658 | C20: =C18+C19 -> -66304 | D20: =D18+D19 -> -848 | E20: =E18+E19 -> -22709 | F20: =F18+F19 -> -12132 | G20: =G18+G19 -> -38535 | H20: =H18+H19 -> -20842
A22: Utilidad antes de impuestos | B22: =B15+B20 -> 449394 | C22: =C15+C20 -> 569202 | D22: =D15+D20 -> 799967 | E22: =E15+E20 -> 610223 | F22: =F15+F20 -> 444224 | G22: =G15+G20 -> 613318 | H22: =H15+H20 -> 1013418
A24: Gasto por impuesto a las ganancias | B24: -148254 | C24: -183643 | D24: -247175 | E24: -202878 | F24: -148560 | G24: -198190 | H24: -293511
A25: UTILIDAD NETA (Resultado del período) | B25: =B22+B24 -> 301140 | C25: =C22+C24 -> 385559 | D25: =D22+D24 -> 552792 | E25: =E22+E24 -> 407345 | F25: =F22+F24 -> 295664 | G25: =G22+G24 -> 415128 | H25: =H22+H24 -> 719907
A27: Ganancia básica por acción común (S/) | B27: 0.83 | C27: 1.062 | D27: 1.218 | E27: 0.898 | F27: 0.493 | G27: 0.519 | H27: 0.72
A29: Margen bruto (%) | B29: =B8/B6 -> 0.41609025 | C29: =C8/C6 -> 0.47914428 | D29: =D8/D6 -> 0.47617093 | E29: =E8/E6 -> 0.42344057 | F29: =F8/F6 -> 0.33530696 | G29: =G8/G6 -> 0.34917001 | H29: =H8/H6 -> 0.3943021
A30: Margen operativo (%) | B30: =B15/B6 -> 0.32123959 | C30: =C15/C6 -> 0.38208435 | D30: =D15/D6 -> 0.3808423 | E30: =E15/E6 -> 0.30273934 | F30: =F15/F6 -> 0.22902424 | G30: =G15/G6 -> 0.24836838 | H30: =H15/H6 -> 0.29769174
A31: Margen neto (%) | B31: =B25/B6 -> 0.20363685 | C31: =C25/C6 -> 0.23180908 | D31: =D25/D6 -> 0.2628904 | E31: =E25/E6 -> 0.19483824 | F31: =F25/F6 -> 0.14838027 | G31: =G25/G6 -> 0.15817166 | H31: =H25/H6 -> 0.20721131

Sheet Flujos de Efectivo
A1: COMPAÑÍA MINERA PODEROSA S.A.
A2: Estado Separado de Flujos de Efectivo (por el año terminado el 31 de diciembre) — Método indirecto
A3: Estados financieros separados (individuales) — Cifras en miles de soles (S/000) — NIIF
A5: Cuenta | B5: 2019 | C5: 2020 | D5: 2021 | E5: 2022 | F5: 2023 | G5: 2024 | H5: 2025
A6: ACTIVIDADES DE OPERACIÓN
A7: Resultado del período (= Utilidad neta, ver hoja Resultados) | B7: =Resultados!B25 -> 301140 | C7: =Resultados!C25 -> 385559 | D7: =Resultados!D25 -> 552792 | E7: =Resultados!E25 -> 407345 | F7: =Resultados!F25 -> 295664 | G7: =Resultados!G25 -> 415128 | H7: =Resultados!H25 -> 719907
A8: Cargos (abonos) a resultado que no representan movimiento de efectivo
A9: Depreciación | B9: 30924 | C9: 34688 | D9: 43070 | E9: 46958 | F9: 45573 | G9: 55153 | H9: 64781
A10: Amortización | B10: 170492 | C10: 208294 | D10: 210130 | E10: 221408 | F10: 233915 | G10: 298798 | H10: 378608
A11: Estimación por deterioro de otras cuentas por cobrar | B11: 5457 | C11: 1398 | D11: 1063 | E11: 411 | F11: 480 | G11: 132 | H11: 76
A12: Provisión para desvalorización de suministros | B12: 0 | C12: 0 | D12: 0 | E12: 0 | F12: 0 | G12: 0 | H12: 240
A13: Recuperación de cuentas incobrables | B13: 0 | C13: 0 | D13: 0 | E13: -26 | F13: -9 | G13: -32 | H13: 0
A14: Provisión por litigios | B14: 328 | C14: 1549 | D14: -1049 | E14: 553 | F14: 657 | G14: 934 | H14: 769
A15: Impuesto a las ganancias diferido | B15: 11770 | C15: -2650 | D15: -6045 | E15: 6652 | F15: 21793 | G15: 30848 | H15: -28835
A16: Gastos de actualización de la provisión para cierre de minas | B16: 1182 | C16: 873 | D16: 877 | E16: 1490 | F16: 3784 | G16: 4924 | H16: 3569
A17: Pérdida (ganancia) en venta de PP&E, neto | B17: 1292 | C17: 4846 | D17: 1118 | E17: 52337 | F17: 10125 | G17: 7900 | H17: -97
A18: Impuesto a las ganancias (gasto del período) | B18: 136484 | C18: 186293 | D18: 253220 | E18: 196226 | F18: 126767 | G18: 167342 | H18: 322346
A19: Diferencia en cambio | B19: -694 | C19: -584 | D19: -5941 | E19: 33899 | F19: 3854 | G19: 4368 | H19: -21980
A20: Costos financieros netos (devengados) | B20: 6520 | C20: 7521 | D20: 5264 | E20: 1512 | F20: 4494 | G20: 29243 | H20: 9413
A21: Cambios netos en activos y pasivos operativos
A22: (Aumento) disminución de cuentas por cobrar comerciales | B22: -3190 | C22: -3165 | D22: 2605 | E22: -2447 | F22: -1998 | G22: -4665 | H22: -14988
A23: (Aumento) disminución de otras cuentas por cobrar | B23: 12890 | C23: 7030 | D23: 96 | E23: -50816 | F23: -26070 | G23: -16591 | H23: 15467
A24: (Aumento) disminución de inventarios | B24: -6785 | C24: -5731 | D24: -9772 | E24: -10688 | F24: 2274 | G24: -29349 | H24: -5480
A25: Aumento (disminución) de gastos contratados por anticipado | B25: -17688 | C25: -377 | D25: 7950 | E25: 2503 | F25: 987 | G25: 2843 | H25: -4945
A26: Aumento (disminución) de cuentas por pagar comerciales | B26: 572 | C26: 14628 | D26: 433 | E26: 17352 | F26: 50277 | G26: 11529 | H26: 81727
A27: Aumento (disminución) de otras cuentas por pagar | B27: 24464 | C27: 51330 | D27: 57757 | E27: -42242 | F27: 39740 | G27: -11936 | H27: 68946
A28: Pago de obligaciones por cierre de unidad minera | B28: -1433 | C28: -369 | D28: -5024 | E28: -3002 | F28: -880 | G28: -1159 | H28: -5315
A29: Efectivo generado por las actividades de operación | B29: =SUM(B7:B28) -> 673725 | C29: =SUM(C7:C28) -> 891133 | D29: =SUM(D7:D28) -> 1108544 | E29: =SUM(E7:E28) -> 879425 | F29: =SUM(F7:F28) -> 811427 | G29: =SUM(G7:G28) -> 965410 | H29: =SUM(H7:H28) -> 1584209
A31: Intereses pagados | B31: -7340 | C31: -6623 | D31: -6183 | E31: -4881 | F31: -8827 | G31: -11459 | H31: -10225
A32: Impuesto a las ganancias pagado | B32: -130875 | C32: -166194 | D32: -240251 | E32: -198988 | F32: -183674 | G32: -135635 | H32: -254824
A33: FLUJO NETO PROVISTO POR ACTIVIDADES DE OPERACIÓN (CFO) | B33: =B29+B31+B32 -> 535510 | C33: =C29+C31+C32 -> 718316 | D33: =D29+D31+D32 -> 862110 | E33: =E29+E31+E32 -> 675556 | F33: =F29+F31+F32 -> 618926 | G33: =G29+G31+G32 -> 818316 | H33: =H29+H31+H32 -> 1319160
A36: ACTIVIDADES DE INVERSIÓN
A37: Cobranza de depósitos a plazos > 90 días | B37: 0 | C37: 0 | D37: 0 | E37: 0 | F37: 171900 | G37: 0 | H37: 0
A38: Apertura de depósitos a plazos > 90 días | B38: 0 | C38: 0 | D38: 0 | E38: -171900 | F38: 0 | G38: 0 | H38: 0
A39: Cobro por venta de propiedades, planta y equipo | B39: 27 | C39: 0 | D39: 677 | E39: 651 | F39: 927 | G39: 674 | H39: 0
A40: Pago por compra de acciones (subsidiarias) | B40: -22517 | C40: 0 | D40: 0 | E40: 0 | F40: 0 | G40: 0 | H40: 0
A41: Pago por compra de activos intangibles | B41: -262994 | C41: -182497 | D41: -211613 | E41: -316482 | F41: -386261 | G41: -528468 | H41: -541823
A42: Pago por compra de propiedades, planta y equipo | B42: -97648 | C42: -86788 | D42: -137600 | E42: -175789 | F42: -194014 | G42: -205738 | H42: -199300
A43: FLUJO NETO UTILIZADO EN ACTIVIDADES DE INVERSIÓN (CFI) | B43: =SUM(B35:B42) -> -383132 | C43: =SUM(C35:C42) -> -269285 | D43: =SUM(D35:D42) -> -348536 | E43: =SUM(E35:E42) -> -663520 | F43: =SUM(F35:F42) -> -407448 | G43: =SUM(G35:G42) -> -733532 | H43: =SUM(H35:H42) -> -741123
A46: ACTIVIDADES DE FINANCIAMIENTO
...

Sheet Ratios Financieros
A1: COMPAÑÍA MINERA PODEROSA S.A.
A2: Análisis de Ratios Financieros 2019–2025
A3: Calculado sobre los estados financieros separados (S/000). Saldos de balance a fin de período.
A5: Indicador | B5: 2019 | C5: 2020 | D5: 2021 | E5: 2022 | F5: 2023 | G5: 2024 | H5: 2025
A6: LIQUIDEZ
A7: Razón corriente (x) | B7: ='Situacion Financiera'!B14/'Situacion Financiera'!B39 -> 0.72730971 | C7: ='Situacion Financiera'!C14/'Situacion Financiera'!C39 -> 1.3739603 | D7: ='Situacion Financiera'!D14/'Situacion Financiera'!D39 -> 1.804572 | E7: ='Situacion Financiera'!E14/'Situacion Financiera'!E39 -> 1.5040665 | F7: ='Situacion Financiera'!F14/'Situacion Financiera'!F39 -> 1.0866633 | G7: ='Situacion Financiera'!G14/'Situacion Financiera'!G39 -> 0.81319041 | H7: ='Situacion Financiera'!H14/'Situacion Financiera'!H39 -> 0.84129771
A8: Prueba ácida (x) | B8: =('Situacion Financiera'!B14-'Situacion Financiera'!B12-'Situacion Financiera'!B13)/'Situacion Financiera'!B39 -> 0.52017693 | C8: =('Situacion Financiera'!C14-'Situacion Financiera'!C12-'Situacion Financiera'!C13)/'Situacion Financiera'!C39 -> 1.1684271 | D8: =('Situacion Financiera'!D14-'Situacion Financiera'!D12-'Situacion Financiera'!D13)/'Situacion Financiera'!D39 -> 1.6215427 | E8: =('Situacion Financiera'!E14-'Situacion Financiera'!E12-'Situacion Financiera'!E13)/'Situacion Financiera'!E39 -> 1.2858826 | F8: =('Situacion Financiera'!F14-'Situacion Financiera'!F12-'Situacion Financiera'!F13)/'Situacion Financiera'!F39 -> 0.8884608 | G8: =('Situacion Financiera'!G14-'Situacion Financiera'!G12-'Situacion Financiera'!G13)/'Situacion Financiera'!G39 -> 0.57680096 | H8: =('Situacion Financiera'!H14-'Situacion Financiera'!H12-'Situacion Financiera'!H13)/'Situacion Financiera'!H39 -> 0.69475252
A9: Razón de efectivo (x) | B9: =('Situacion Financiera'!B8+'Situacion Financiera'!B9)/'Situacion Financiera'!B39 -> 0.40620845 | C9: =('Situacion Financiera'!C8+'Situacion Financiera'!C9)/'Situacion Financiera'!C39 -> 1.0813631 | D9: =('Situacion Financiera'!D8+'Situacion Financiera'!D9)/'Situacion Financiera'!D39 -> 1.5546264 | E9: =('Situacion Financiera'!E8+'Situacion Financiera'!E9)/'Situacion Financiera'!E39 -> 1.094008 | F9: =('Situacion Financiera'!F8+'Situacion Financiera'!F9)/'Situacion Financiera'!F39 -> 0.64882966 | G9: =('Situacion Financiera'!G8+'Situacion Financiera'!G9)/'Situacion Financiera'!G39 -> 0.31411698 | H9: =('Situacion Financiera'!H8+'Situacion Financiera'!H9)/'Situacion Financiera'!H39 -> 0.54387768
A10: Capital de trabajo (S/000) | B10: ='Situacion Financiera'!B14-'Situacion Financiera'!B39 -> -79772 | C10: ='Situacion Financiera'!C14-'Situacion Financiera'!C39 -> 126602 | D10: ='Situacion Financiera'!D14-'Situacion Financiera'!D39 -> 321931 | E10: ='Situacion Financiera'!E14-'Situacion Financiera'!E39 -> 196344 | F10: ='Situacion Financiera'!F14-'Situacion Financiera'!F39 -> 37047 | G10: ='Situacion Financiera'!G14-'Situacion Financiera'!G39 -> -87904 | H10: ='Situacion Financiera'!H14-'Situacion Financiera'!H39 -> -123820
A11: Capital de trabajo / Ventas (%) | B11: =B10/Resultados!B6 -> -0.05394341 | C11: =C10/Resultados!C6 -> 0.076116737 | D11: =D10/Resultados!D6 -> 0.15310021 | E11: =E10/Resultados!E6 -> 0.093913807 | F11: =F10/Resultados!F6 -> 0.018592198 | G11: =G10/Resultados!G6 -> -0.033493095 | H11: =H10/Resultados!H6 -> -0.035639193
A13: GESTIÓN / ACTIVIDAD
A14: Rotación de cuentas por cobrar (x) | B14: =Resultados!B6/'Situacion Financiera'!B10 -> 153.6904 | C14: =Resultados!C6/'Situacion Financiera'!C10 -> 130.07437 | D14: =Resultados!D6/'Situacion Financiera'!D10 -> 206.49583 | E14: =Resultados!E6/'Situacion Financiera'!E10 -> 165.5331 | F14: =Resultados!F6/'Situacion Financiera'!F10 -> 136.2189 | G14: =Resultados!G6/'Situacion Financiera'!G10 -> 136.03592 | H14: =Resultados!H6/'Situacion Financiera'!H10 -> 101.34666
A15: Días de cobro | B15: =365/B14 -> 2.3749044 | C15: =365/C14 -> 2.806087 | D15: =365/D14 -> 1.7675902 | E15: =365/E14 -> 2.2049971 | F15: =365/F14 -> 2.6795108 | G15: =365/G14 -> 2.6831149 | H15: =365/H14 -> 3.6014999
A16: Rotación de inventarios (x) | B16: =-Resultados!B7/'Situacion Financiera'!B12 -> 19.468604 | C16: =-Resultados!C7/'Situacion Financiera'!C12 -> 17.297321 | D16: =-Resultados!D7/'Situacion Financiera'!D12 -> 18.402165 | E16: =-Resultados!E7/'Situacion Financiera'!E12 -> 17.087251 | F16: =-Resultados!F7/'Situacion Financiera'!F12 -> 19.400527 | G16: =-Resultados!G7/'Situacion Financiera'!G12 -> 17.497926 | H16: =-Resultados!H7/'Situacion Financiera'!H12 -> 20.458638
A17: Días de inventario | B17: =365/B16 -> 18.748134 | C17: =365/C16 -> 21.101534 | D17: =365/D16 -> 19.834623 | E17: =365/E16 -> 21.360956 | F17: =365/F16 -> 18.813922 | G17: =365/G16 -> 20.859615 | H17: =365/H16 -> 17.840875
A18: Rotación de cuentas por pagar (x) | B18: =-Resultados!B7/'Situacion Financiera'!B30 -> 12.165101 | C18: =-Resultados!C7/'Situacion Financiera'!C30 -> 10.119485 | D18: =-Resultados!D7/'Situacion Financiera'!D30 -> 12.801655 | E18: =-Resultados!E7/'Situacion Financiera'!E30 -> 11.658346 | F18: =-Resultados!F7/'Situacion Financiera'!F30 -> 6.2940712 | G18: =-Resultados!G7/'Situacion Financiera'!G30 -> 7.6956312 | H18: =-Resultados!H7/'Situacion Financiera'!H30 -> 6.9293321
A19: Días de pago | B19: =365/B18 -> 30.003862 | C19: =365/C18 -> 36.069029 | D19: =365/D18 -> 28.511938 | E19: =365/E18 -> 31.308044 | F19: =365/F18 -> 57.991082 | G19: =365/G18 -> 47.429508 | H19: =365/H18 -> 52.67463
A20: Ciclo de conversión de efectivo (días) | B20: =B15+B17-B19 -> -8.8808238 | C20: =C15+C17-C19 -> -12.161408 | D20: =D15+D17-D19 -> -6.9097258 | E20: =E15+E17-E19 -> -7.7420911 | F20: =F15+F17-F19 -> -36.497649 | G20: =G15+G17-G19 -> -23.886777 | H20: =H15+H17-H19 -> -31.232254
A21: Rotación de activos totales (x) | B21: =Resultados!B6/'Situacion Financiera'!B25 -> 1.0635103 | C21: =Resultados!C6/'Situacion Financiera'!C25 -> 0.97362322 | D21: =Resultados!D6/'Situacion Financiera'!D25 -> 1.0147178 | E21: =Resultados!E6/'Situacion Financiera'!E25 -> 0.99514774 | F21: =Resultados!F6/'Situacion Financiera'!F25 -> 0.85611784 | G21: =Resultados!G6/'Situacion Financiera'!G25 -> 1.0321497 | H21: =Resultados!H6/'Situacion Financiera'!H25 -> 1.0895061
A22: Rotación de activo fijo – PP&E (x) | B22: =Resultados!B6/'Situacion Financiera'!B20 -> 2.6628942 | C22: =Resultados!C6/'Situacion Financiera'!C20 -> 2.4873945 | D22: =Resultados!D6/'Situacion Financiera'!D20 -> 2.7621313 | E22: =Resultados!E6/'Situacion Financiera'!E20 -> 2.5203467 | F22: =Resultados!F6/'Situacion Financiera'!F20 -> 1.9236287 | G22: =Resultados!G6/'Situacion Financiera'!G20 -> 2.3712961 | H22: =Resultados!H6/'Situacion Financiera'!H20 -> 2.6613339
A24: ENDEUDAMIENTO Y SOLVENCIA
A25: Deuda financiera total (S/000) | B25: ='Situacion Financiera'!B33+'Situacion Financiera'!B34+'Situacion Financiera'!B43+'Situacion Financiera'!B44 -> 156041 | C25: ='Situacion Financiera'!C33+'Situacion Financiera'!C34+'Situacion Financiera'!C43+'Situacion Financiera'!C44 -> 130697 | D25: ='Situacion Financiera'!D33+'Situacion Financiera'!D34+'Situacion Financiera'!D43+'Situacion Financiera'!D44 -> 128671 | E25: ='Situacion Financiera'!E33+'Situacion Financiera'!E34+'Situacion Financiera'!E43+'Situacion Financiera'!E44 -> 105718 | F25: ='Situacion Financiera'!F33+'Situacion Financiera'!F34+'Situacion Financiera'!F43+'Situacion Financiera'!F44 -> 163958 | G25: ='Situacion Financiera'!G33+'Situacion Financiera'!G34+'Situacion Financiera'!G43+'Situacion Financiera'!G44 -> 132065 | H25: ='Situacion Financiera'!H33+'Situacion Financiera'!H34+'Situacion Financiera'!H43+'Situacion Financiera'!H44 -> 205664
A26: Efectivo y depósitos (S/000) | B26: ='Situacion Financiera'!B8+'Situacion Financiera'!B9 -> 118831 | C26: ='Situacion Financiera'!C8+'Situacion Financiera'!C9 -> 366089 | D26: ='Situacion Financiera'!D8+'Situacion Financiera'!D9 -> 622048 | E26: ='Situacion Financiera'!E8+'Situacion Financiera'!E9 -> 426138 | F26: ='Situacion Financiera'!F8+'Situacion Financiera'!F9 -> 277363 | G26: ='Situacion Financiera'!G8+'Situacion Financiera'!G9 -> 147809 | H26: ='Situacion Financiera'!H8+'Situacion Financiera'!H9 -> 424335
A27: Deuda financiera neta (S/000) | B27: =B25-B26 -> 37210 | C27: =C25-C26 -> -235392 | D27: =D25-D26 -> -493377 | E27: =E25-E26 -> -320420 | F27: =F25-F26 -> -113405 | G27: =G25-G26 -> -15744 | H27: =H25-H26 -> -218671
A28: Pasivo total / Activo total (%) | B28: ='Situacion Financiera'!B49/'Situacion Financiera'!B25 -> 0.30463115 | C28: ='Situacion Financiera'!C49/'Situacion Financiera'!C25 -> 0.29967611 | D28: ='Situacion Financiera'!D49/'Situacion Financiera'!D25 -> 0.2675008 | E28: ='Situacion Financiera'!E49/'Situacion Financiera'!E25 -> 0.24080182 | F28: ='Situacion Financiera'!F49/'Situacion Financiera'!F25 -> 0.29296948 | G28: ='Situacion Financiera'!G49/'Situacion Financiera'!G25 -> 0.25926983 | H28: ='Situacion Financiera'!H49/'Situacion Financiera'!H25 -> 0.30790625
A29: Pasivo total / Patrimonio (x) | B29: ='Situacion Financiera'!B49/'Situacion Financiera'!B56 -> 0.43808569 | C29: ='Situacion Financiera'!C49/'Situacion Financiera'!C56 -> 0.42791074 | D29: ='Situacion Financiera'!D49/'Situacion Financiera'!D56 -> 0.36518921 | E29: ='Situacion Financiera'!E49/'Situacion Financiera'!E56 -> 0.31717913 | F29: ='Situacion Financiera'!F49/'Situacion Financiera'!F56 -> 0.4143661 | G29: ='Situacion Financiera'!G49/'Situacion Financiera'!G56 -> 0.35001927 | H29: ='Situacion Financiera'!H49/'Situacion Financiera'!H56 -> 0.44489096
A30: Patrimonio / Activo total (%) | B30: ='Situacion Financiera'!B56/'Situacion Financiera'!B25 -> 0.69536885 | C30: ='Situacion Financiera'!C56/'Situacion Financiera'!C25 -> 0.70032389 | D30: ='Situacion Financiera'!D56/'Situacion Financiera'!D25 -> 0.7324992 | E30: ='Situacion Financiera'!E56/'Situacion Financiera'!E25 -> 0.75919818 | F30: ='Situacion Financiera'!F56/'Situacion Financiera'!F25 -> 0.70703052 | G30: ='Situacion Financiera'!G56/'Situacion Financiera'!G25 -> 0.74073017 | H30: ='Situacion Financiera'!H56/'Situacion Financiera'!H25 -> 0.69209375
A31: Pasivo corriente / Pasivo total (%) | B31: ='Situacion Financiera'!B39/'Situacion Financiera'!B49 -> 0.6906152 | C31: ='Situacion Financiera'!C39/'Situacion Financiera'!C49 -> 0.66129237 | D31: ='Situacion Financiera'!D39/'Situacion Financiera'!D49 -> 0.72182354 | E31: ='Situacion Financiera'!E39/'Situacion Financiera'!E49 -> 0.76996215 | F31: ='Situacion Financiera'!F39/'Situacion Financiera'!F49 -> 0.62691216 | G31: ='Situacion Financiera'!G39/'Situacion Financiera'!G49 -> 0.71375114 | H31: ='Situacion Financiera'!H39/'Situacion Financiera'!H49 -> 0.79461331
A32: Deuda financiera / EBITDA (x) | B32: =B25/B38 -> 0.23067019 | C32: =C25/C38 -> 0.14877494 | D32: =D25/D38 -> 0.12207701 | E32: =E25/E38 -> 0.11729528 | F32: =F25/F38 -> 0.22281625 | G32: =G25/G38 -> 0.13130292 | H32: =H25/H38 -> 0.13918326
A33: Deuda financiera neta / EBITDA (x) | B33: =B27/B38 -> 0.055006297 | C33: =C27/C38 -> -0.2679513 | D33: =D27/D38 -> -0.46809296 | E33: =E27/E38 -> -0.3555095 | F33: =F27/F38 -> -0.15411555 | G33: =G27/G38 -> -0.015653149 | H33: =H27/H38 -> -0.14798575
A34: Cobertura de intereses – EBIT (x) | B34: =Resultados!B15/-Resultados!B19 -> 17.28782 | C34: =Resultados!C15/-Resultados!C19 -> 9.3593025 | D34: =Resultados!D15/-Resultados!D19 -> 101.24083 | E34: =Resultados!E15/-Resultados!E19 -> 15.414808 | F34: =Resultados!F15/-Resultados!F19 -> 20.61601 | G34: =Resultados!G15/-Resultados!G19 -> 14.386833 | H34: =Resultados!H15/-Resultados!H19 -> 36.809026
A35: Cobertura de intereses – EBITDA (x) | B35: =B38/-Resultados!B19 -> 24.617635 | C35: =C38/-Resultados!C19 -> 12.937777 | D35: =D38/-Resultados!D19 -> 133.25095 | E35: =E38/-Resultados!E19 -> 21.950755 | F35: =F38/-Resultados!F19 -> 33.241959 | G35: =G38/-Resultados!G19 -> 22.198768 | H35: =H38/-Resultados!H19 -> 52.589117
A37: RENTABILIDAD
A38: EBITDA (S/000) | B38: =Resultados!B15+'Flujos de Efectivo'!B9+'Flujos de Efectivo'!B10 -> 676468 | C38: =Resultados!C15+'Flujos de Efectivo'!C9+'Flujos de Efectivo'!C10 -> 878488 | D38: =Resultados!D15+'Flujos de Efectivo'!D9+'Flujos de Efectivo'!D10 -> 1054015 | E38: =Resultados!E15+'Flujos de Efectivo'!E9+'Flujos de Efectivo'!E10 -> 901298 | F38: =Resultados!F15+'Flujos de Efectivo'!F9+'Flujos de Efectivo'!F10 -> 735844 | G38: =Resultados!G15+'Flujos de Efectivo'!G9+'Flujos de Efectivo'!G10 -> 1005804 | H38: =Resultados!H15+'Flujos de Efectivo'!H9+'Flujos de Efectivo'!H10 -> 1477649
A39: Margen bruto (%) | B39: =Resultados!B8/Resultados!B6 -> 0.41609025 | C39: =Resultados!C8/Resultados!C6 -> 0.47914428 | D39: =Resultados!D8/Resultados!D6 -> 0.47617093 | E39: =Resultados!E8/Resultados!E6 -> 0.42344057 | F39: =Resultados!F8/Resultados!F6 -> 0.33530696 | G39: =Resultados!G8/Resultados!G6 -> 0.34917001 | H39: =Resultados!H8/Resultados!H6 -> 0.3943021
A40: Margen operativo (%) | B40: =Resultados!B15/Resultados!B6 -> 0.32123959 | C40: =Resultados!C15/Resultados!C6 -> 0.38208435 | D40: =Resultados!D15/Resultados!D6 -> 0.3808423 | E40: =Resultados!E15/Resultados!E6 -> 0.30273934 | F40: =Resultados!F15/Resultados!F6 -> 0.22902424 | G40: =Resultados!G15/Resultados!G6 -> 0.24836838 | H40: =Resultados!H15/Resultados!H6 -> 0.29769174
A41: Margen EBITDA (%) | B41: =B38/Resultados!B6 -> 0.45744109 | C41: =C38/Resultados!C6 -> 0.52817207 | D41: =D38/Resultados!D6 -> 0.50125621 | E41: =E38/Resultados!E6 -> 0.43110218 | F41: =F38/Resultados!F6 -> 0.36928651 | G41: =G38/Resultados!G6 -> 0.38323044 | H41: =H38/Resultados!H6 -> 0.42531269
A42: Margen neto (%) | B42: =Resultados!B25/Resultados!B6 -> 0.20363685 | C42: =Resultados!C25/Resultados!C6 -> 0.23180908 | D42: =Resultados!D25/Resultados!D6 -> 0.2628904 | E42: =Resultados!E25/Resultados!E6 -> 0.19483824 | F42: =Resultados!F25/Resultados!F6 -> 0.14838027 | G42: =Resultados!G25/Resultados!G6 -> 0.15817166 | H42: =Resultados!H25/Resultados!H6 -> 0.20721131
A43: Tasa efectiva de impuestos (%) | B43: =-Resultados!B24/Resultados!B22 -> 0.3298976 | C43: =-Resultados!C24/Resultados!C22 -> 0.32263239 | D43: =-Resultados!D24/Resultados!D22 -> 0.3089815 | E43: =-Resultados!E24/Resultados!E22 -> 0.33246534 | F43: =-Resultados!F24/Resultados!F22 -> 0.33442588 | G43: =-Resultados!G24/Resultados!G22 -> 0.32314395 | H43: =-Resultados!H24/Resultados!H22 -> 0.28962481
A44: ROA – Utilidad neta / Activo total (%) | B44: =Resultados!B25/'Situacion Financiera'!B25 -> 0.21656989 | C44: =Resultados!C25/'Situacion Financiera'!C25 -> 0.2256947 | D44: =Resultados!D25/'Situacion Financiera'!D25 -> 0.26675958 | E44: =Resultados!E25/'Situacion Financiera'!E25 -> 0.19389284 | F44: =Resultados!F25/'Situacion Financiera'!F25 -> 0.12703099 | G44: =Resultados!G25/'Situacion Financiera'!G25 -> 0.16325683 | H44: =Resultados!H25/'Situacion Financiera'!H25 -> 0.22575799
...

Sheet CCE ROA ROE
A1: COMPAÑÍA MINERA PODEROSA S.A. — CCE, ROA y ROE (2019–2025)
A2: Calculado sobre los estados financieros separados (S/000), saldos de cierre. CCE = PPI + PPC − PPP
A4: CICLO DE CONVERSIÓN DE EFECTIVO (días)
A5: Indicador | B5: 2019 | C5: 2020 | D5: 2021 | E5: 2022 | F5: 2023 | G5: 2024 | H5: 2025
A6: PPI – Periodo promedio de inventarios | B6: =365*'Situacion Financiera'!B12/-Resultados!B7 -> 18.748134 | C6: =365*'Situacion Financiera'!C12/-Resultados!C7 -> 21.101534 | D6: =365*'Situacion Financiera'!D12/-Resultados!D7 -> 19.834623 | E6: =365*'Situacion Financiera'!E12/-Resultados!E7 -> 21.360956 | F6: =365*'Situacion Financiera'!F12/-Resultados!F7 -> 18.813922 | G6: =365*'Situacion Financiera'!G12/-Resultados!G7 -> 20.859615 | H6: =365*'Situacion Financiera'!H12/-Resultados!H7 -> 17.840875
A7: PPC – Periodo promedio de cobro | B7: =365*'Situacion Financiera'!B10/Resultados!B6 -> 2.3749044 | C7: =365*'Situacion Financiera'!C10/Resultados!C6 -> 2.806087 | D7: =365*'Situacion Financiera'!D10/Resultados!D6 -> 1.7675902 | E7: =365*'Situacion Financiera'!E10/Resultados!E6 -> 2.2049971 | F7: =365*'Situacion Financiera'!F10/Resultados!F6 -> 2.6795108 | G7: =365*'Situacion Financiera'!G10/Resultados!G6 -> 2.6831149 | H7: =365*'Situacion Financiera'!H10/Resultados!H6 -> 3.6014999
A8: PPP – Periodo promedio de pago | B8: =365*'Situacion Financiera'!B30/-Resultados!B7 -> 30.003862 | C8: =365*'Situacion Financiera'!C30/-Resultados!C7 -> 36.069029 | D8: =365*'Situacion Financiera'!D30/-Resultados!D7 -> 28.511938 | E8: =365*'Situacion Financiera'!E30/-Resultados!E7 -> 31.308044 | F8: =365*'Situacion Financiera'!F30/-Resultados!F7 -> 57.991082 | G8: =365*'Situacion Financiera'!G30/-Resultados!G7 -> 47.429508 | H8: =365*'Situacion Financiera'!H30/-Resultados!H7 -> 52.67463
A9: CCE – Ciclo de conversión de efectivo | B9: =B6+B7-B8 -> -8.8808238 | C9: =C6+C7-C8 -> -12.161408 | D9: =D6+D7-D8 -> -6.9097258 | E9: =E6+E7-E8 -> -7.7420911 | F9: =F6+F7-F8 -> -36.497649 | G9: =G6+G7-G8 -> -23.886777 | H9: =H6+H7-H8 -> -31.232254
A12: ROA – RENTABILIDAD SOBRE ACTIVOS (Utilidad neta / Activo total)
A13: Indicador | B13: 2019 | C13: 2020 | D13: 2021 | E13: 2022 | F13: 2023 | G13: 2024 | H13: 2025
A14: ROA | B14: =Resultados!B25/'Situacion Financiera'!B25 -> 0.21656989 | C14: =Resultados!C25/'Situacion Financiera'!C25 -> 0.2256947 | D14: =Resultados!D25/'Situacion Financiera'!D25 -> 0.26675958 | E14: =Resultados!E25/'Situacion Financiera'!E25 -> 0.19389284 | F14: =Resultados!F25/'Situacion Financiera'!F25 -> 0.12703099 | G14: =Resultados!G25/'Situacion Financiera'!G25 -> 0.16325683 | H14: =Resultados!H25/'Situacion Financiera'!H25 -> 0.22575799
A17: ROE – RENTABILIDAD SOBRE PATRIMONIO (Utilidad neta / Patrimonio)
A18: Indicador | B18: 2019 | C18: 2020 | D18: 2021 | E18: 2022 | F18: 2023 | G18: 2024 | H18: 2025
A19: ROE | B19: =Resultados!B25/'Situacion Financiera'!B56 -> 0.31144606 | C19: =Resultados!C25/'Situacion Financiera'!C56 -> 0.32227189 | D19: =Resultados!D25/'Situacion Financiera'!D56 -> 0.3641773 | E19: =Resultados!E25/'Situacion Financiera'!E56 -> 0.2553916 | F19: =Resultados!F25/'Situacion Financiera'!F56 -> 0.17966833 | G19: =Resultados!G25/'Situacion Financiera'!G56 -> 0.22039987 | H19: =Resultados!H25/'Situacion Financiera'!H56 -> 0.32619567

Sheet Notas y Fuentes
A1: COMPAÑÍA MINERA PODEROSA S.A.
A2: Notas metodológicas, fuentes documentales y observaciones de un CFA Charterholder
A4: Fuentes por año fiscal (archivo PDF cargado por el usuario)
A5: 2019 | B5: memoria2020.pdf — Memoria/Informe Anual de Sostenibilidad 2020 (columna comparativa 2019), páginas de Estados Financieros separados auditados. No se cargó un EEFF individual de 2019; se usó el comparativo del informe 2020, que es el propio ejercicio auditado para 2019.
A6: 2020 | B6: memoria2020.pdf — Estado Separado de Situación Financiera, de Resultados y de Flujos de Efectivo al 31/12/2020, dictaminados por auditor independiente (opinión sin salvedades).
A7: 2021 | B7: estadosfinancieros2021.pdf — EEFF Separados auditados al 31/12/2021 (columna corriente).
A8: 2022 | B8: estadosfinancieros2022.pdf — EEFF Separados auditados al 31/12/2022 (columna corriente). Se usó el reporte propio del ejercicio 2022, no el comparativo del informe 2023 (ver reclasificaciones abajo).
A9: 2023 | B9: estadosfinancieros2023.pdf — EEFF Separados auditados al 31/12/2023 (columna corriente).
A10: 2024 | B10: estadosfinancieros2024.pdf — EEFF Separados auditados al 31/12/2024 (columna corriente). Se usó el reporte propio del ejercicio 2024, no el comparativo del informe 2025 (ver reclasificaciones abajo).
A11: 2025 | B11: estadosfinancieros2025.pdf — EEFF Separados auditados al 31/12/2025 (columna corriente).
A13: Criterio de selección de la fuente
B14: Para cada año se utilizó el Estado Financiero Separado tal como fue emitido y dictaminado para ese ejercicio específico (columna 'año corriente' de su propio reporte auditado), y no la columna comparativa que aparece en el reporte del año siguiente. Esto es consistente con la práctica de un analista CFA: la cifra originalmente auditada de cada cierre es la fuente primaria; las cifras comparativas de reportes posteriores pueden incorporar reclasificaciones de presentación (sin afectar los totales) que conviene documentar por separado en lugar de mezclar bases.
A16: Reclasificaciones detectadas entre reportes consecutivos
A17: 2022 → 2023 | B17: El informe de 2023 reclasifica ~S/56.8 MM entre 'Cuentas por pagar comerciales' y 'Otras cuentas por pagar' del saldo 2022 (2022 propio: 103,394 / 127,512; comparativo en informe 2023: 160,155 / 70,751). El Total pasivo corriente 2022 (389,520) no se ve afectado.
A18: 2024 → 2025 | B18: El informe de 2025 reclasifica ~S/7.1 MM de 'Gastos contratados por anticipado' de corriente a no corriente, y separa ~S/5.4 MM de 'Otras cuentas por cobrar' hacia 'Activo por impuesto a las ganancias' del saldo 2024 (2024 propio: activo corriente 382,650; comparativo en informe 2025: 375,566, con el mismo Total activo 2,542,791). Asimismo, el CFI 2024 cambia de -733,532 (propio) a -727,646 (comparativo) por una reclasificación menor entre compras de intangibles y de PP&E; se preservó la cifra del reporte propio de 2024.
A20: Controles de calidad aplicados
B21: 1) Cuadre contable: Total Activo = Total Pasivo + Patrimonio verificado en los 7 años (diferencia = 0 en la fila de verificación de la hoja 'Situacion Financiera').
B22: 2) Puente de utilidad neta: la fila 'Resultado del período' del Estado de Flujos de Efectivo está enlazada por fórmula a la Utilidad Neta del Estado de Resultados (no se reescribió el valor).
B23: 3) Conciliación de caja: el saldo 'Efectivo y equivalentes al final del año' del Estado de Flujos de Efectivo fue verificado contra el efectivo reportado en el Estado de Situación Financiera para los 7 años (fila de verificación con fórmula cruzada entre hojas).
B24: 4) Encadenamiento interanual: el saldo inicial de efectivo de cada año coincide con el saldo final del año anterior en los 7 ejercicios.
B25: 5) Todas las cifras están en miles de soles (S/000), moneda funcional y de presentación de la Compañía, sin ajustar por inflación ni reexpresión.
A27: Alcance
B28: Estados financieros SEPARADOS (individuales) de Compañía Minera Poderosa S.A., preparados bajo NIIF (IFRS), en soles peruanos (S/), no auditados por Claude — transcritos y verificados aritméticamente a partir de los PDF cargados por el usuario. No incluye estados financieros consolidados (con subsidiarias), los cuales la propia Compañía indica que se presentan por separado en cada informe.
