Workbook

Sheet Portada
A2: COMPAÑÍA MINERA PODEROSA S.A.
A3: Estados Financieros Separados Auditados — Serie 2020 a 2025
A4: Base de datos elaborada para trabajo de investigación / tesis de bachiller
A6: CONTENIDO DEL LIBRO
A7: • ESF — Estado Separado de Situación Financiera (Balance General), 2020-2025
A8: • ERI — Estado Separado de Resultados y Otros Resultados Integrales, 2020-2025
A9: • ECP — Estado Separado de Cambios en el Patrimonio, 2020-2025
A10: • EFE — Estado Separado de Flujos de Efectivo, 2020-2025
A11: • Ratios — Indicadores financieros (liquidez, solvencia, rentabilidad, eficiencia, por acción)
A13: UNIDADES Y MONEDA
A14: Todas las cifras están expresadas en miles de soles (S/000), salvo que se indique lo contrario (p. ej. ganancia por acción, en soles por acción). La moneda funcional y de presentación de la Compañía es el Sol (S/).
A16: METODOLOGÍA DE EXTRACCIÓN
... A30: Esta base de datos es un insumo de trabajo para fines académicos. Se recomienda contrastar cualquier cifra crítica contra el PDF fuente y las notas explicativas a los estados financieros antes de usarla en el documento final de tesis.

Sheet ESF
A1: COMPAÑÍA MINERA PODEROSA S.A.
A2: Estado Separado de Situación Financiera
A3: Al 31 de diciembre de cada año — cifras en miles de soles (S/000)
A5: Concepto | B5: Nota | D5: 2020 | E5: 2021 | F5: 2022 | G5: 2023 | H5: 2024 | I5: 2025
A6: ACTIVO
A7: Activo corriente
A8: Efectivo y equivalentes de efectivo | B8: 6 | D8: 366089 | E8: 622048 | F8: 254238 | G8: 277363 | H8: 147809 | I8: 424335
A9: Otros activos financieros (depósitos > 90 días) | B9: 6 | F9: 171900 | G9: 0
A10: Cuentas por cobrar comerciales | B10: 7 | D10: 12787 | E10: 10183 | F10: 12630 | G10: 14628 | H10: 19293 | I10: 34281
A11: Otras cuentas por cobrar | B11: 8 | D11: 16688 | E11: 16592 | F11: 62109 | G11: 87810 | H11: 104314 | I11: 83432
A12: Activo por impuesto a las ganancias | B12: 26 | H12: 0 | I12: 0
A13: Inventarios | B13: 9 | D13: 50084 | E13: 59856 | F13: 70544 | G13: 68270 | H13: 97619 | I13: 102859
A14: Gastos contratados por anticipado | B14: 10 | D14: 19498 | E14: 13379 | F14: 14443 | G14: 16458 | H14: 13615 | I14: 11476
A15: Total activo corriente | D15: =D8+D9+D10+D11+D12+D13+D14 -> 465146 | E15: =E8+E9+E10+E11+E12+E13+E14 -> 722058 | F15: =F8+F9+F10+F11+F12+F13+F14 -> 585864 | G15: =G8+G9+G10+G11+G12+G13+G14 -> 464529 | H15: =H8+H9+H10+H11+H12+H13+H14 -> 382650 | I15: =I8+I9+I10+I11+I12+I13+I14 -> 656383
A16: Activo no corriente
A17: Otras cuentas por cobrar (no corriente) | B17: 8 | F17: 5299 | G17: 5668 | H17: 5755 | I17: 5755
A18: Inversiones en subsidiarias y asociadas | B18: 11 | D18: 25460 | E18: 25460 | F18: 25837 | G18: 25460 | H18: 25460 | I18: 25460
A19: Gastos contratados por anticipado (no corriente) | B19: 10 | D19: 20411 | E19: 18580 | F19: 15013 | G19: 12011 | H19: 12011 | I19: 19095
A20: Propiedades, planta y equipo | B20: 12 | D20: 668676 | E20: 761277 | F20: 829522 | G20: 1035860 | H20: 1106796 | I20: 1305460
A21: Activos por derecho de uso | B21: 13 | D21: 21982 | E21: 30105 | F21: 29499 | G21: 21778 | H21: 17749 | I21: 13544
A22: Activos intangibles | B22: 14 | D22: 506646 | E22: 514768 | F22: 609843 | G22: 762189 | H22: 992370 | I22: 1163147
A23: Total activo no corriente | D23: =D17+D18+D19+D20+D21+D22 -> 1243175 | E23: =E17+E18+E19+E20+E21+E22 -> 1350190 | F23: =F17+F18+F19+F20+F21+F22 -> 1515013 | G23: =G17+G18+G19+G20+G21+G22 -> 1862966 | H23: =H17+H18+H19+H20+H21+H22 -> 2160141 | I23: =I17+I18+I19+I20+I21+I22 -> 2532461
A24: TOTAL ACTIVO | D24: =D15+D23 -> 1708321 | E24: =E15+E23 -> 2072248 | F24: =F15+F23 -> 2100877 | G24: =G15+G23 -> 2327495 | H24: =H15+H23 -> 2542791 | I24: =I15+I23 -> 3188844
A26: PASIVO
A27: Pasivo corriente
A28: Cuentas por pagar comerciales | B28: 15 | D28: 85609 | E28: 86042 | F28: 103394 | G28: 210432 | H28: 221961 | I28: 303688
A29: Otras cuentas por pagar | B29: 16 | D29: 109926 | E29: 156479 | F29: 127512 | G29: 67911 | H29: 89451 | I29: 117990
A30: Pasivo por impuesto a las ganancias | B30: 26 | H30: 0 | I30: 62029
A31: Otros pasivos financieros | B31: 17 | D31: 65650 | E31: 68532 | F31: 88270 | G31: 98735 | H31: 100100 | I31: 199052
A32: Instrumentos financieros derivados | B32: 21 | D32: 6748 | E32: 0
A33: Pasivos por arrendamientos | B33: 13 | D33: 10869 | E33: 11517 | F33: 5697 | G33: 4480 | H33: 1904 | I33: 1418
A34: Beneficios a los empleados | B34: 18 | D34: 52331 | E34: 71526 | F34: 59491 | G34: 41236 | H34: 51276 | I34: 91718
A35: Provisiones | B35: 19 | D35: 4014 | E35: 2283 | F35: 1575 | G35: 1765 | H35: 2470 | I35: 2472
A36: Provisión para cierre de minas (porción corriente) | B36: 20 | D36: 3397 | E36: 3748 | F36: 3581 | G36: 2923 | H36: 3392 | I36: 1836
A37: Total pasivo corriente | D37: =D28+D29+D30+D31+D32+D33+D34+D35+D36 -> 338544 | E37: =E28+E29+E30+E31+E32+E33+E34+E35+E36 -> 400127 | F37: =F28+F29+F30+F31+F32+F33+F34+F35+F36 -> 389520 | G37: =G28+G29+G30+G31+G32+G33+G34+G35+G36 -> 427482 | H37: =H28+H29+H30+H31+H32+H33+H34+H35+H36 -> 470554 | I37: =I28+I29+I30+I31+I32+I33+I34+I35+I36 -> 780203
A38: Pasivo no corriente
A39: Otras cuentas por pagar | B39: 16 | D39: 2659 | E39: 1660 | F39: 420 | G39: 241 | H39: 209 | I39: 174
A40: Otros pasivos financieros | B40: 17 | D40: 43224 | E40: 31402 | F40: 0 | G40: 51982 | H40: 22620 | I40: 0
A41: Pasivos por arrendamientos | B41: 13 | D41: 10954 | E41: 17220 | F41: 11751 | G41: 8761 | H41: 7441 | I41: 5194
A42: Provisión para cierre de minas | B42: 20 | D42: 74049 | E42: 67451 | F42: 61084 | G42: 128506 | H42: 62684 | I42: 129368
...

Sheet ERI
A1: COMPAÑÍA MINERA PODEROSA S.A.
A2: Estado Separado de Resultados y Otros Resultados Integrales
A3: Por los años terminados el 31 de diciembre — cifras en miles de soles (S/000), salvo utilidad por acción
A5: Concepto | B5: Nota | D5: 2020 | E5: 2021 | F5: 2022 | G5: 2023 | H5: 2024 | I5: 2025
A6: Ingresos de actividades ordinarias | B6: 27/28 | D6: 1663261 | E6: 2102747 | F6: 2090683 | G6: 1992610 | H6: 2624541 | I6: 3474265
A7: Costo de ventas | B7: 28/29 | D7: -866319 | E7: -1101480 | F7: -1205403 | G7: -1324474 | H7: -1708130 | I7: -2104355
A8: Utilidad (ganancia) bruta | D8: =D6+D7 -> 796942 | E8: =E6+E7 -> 1001267 | F8: =F6+F7 -> 885280 | G8: =G6+G7 -> 668136 | H8: =H6+H7 -> 916411 | I8: =I6+I7 -> 1369910
A10: Ingresos (gastos) de operación
A11: Gastos de venta | B11: 29/30 | D11: -36080 | E11: -54900 | F11: -52160 | G11: -53764 | H11: -76754 | I11: -107225
A12: Gastos de administración | B12: 30/31 | D12: -128472 | E12: -162202 | F12: -159221 | G12: -171810 | H12: -200960 | I12: -257099
A13: Otros ingresos | B13: 34/35 | D13: 7962 | E13: 17768 | F13: 12917 | G13: 24406 | H13: 21860 | I13: 29686
A14: Otros gastos | B14: 34/35 | D14: -4846 | E14: -1118 | F14: -53884 | G14: -10612 | H14: -8704 | I14: -1012
A15: Utilidad (resultado) operativo | D15: =D8+D11+D12+D13+D14 -> 635506 | E15: =E8+E11+E12+E13+E14 -> 800815 | F15: =F8+F11+F12+F13+F14 -> 632932 | G15: =G8+G11+G12+G13+G14 -> 456356 | H15: =H8+H11+H12+H13+H14 -> 651853 | I15: =I8+I11+I12+I13+I14 -> 1034260
A17: Ingresos financieros | B17: 32/33 | D17: 1597 | E17: 7062 | F17: 18351 | G17: 10004 | H17: 6774 | I17: 7256
A18: Gastos (costos) financieros | B18: 32/33 | D18: -67901 | E18: -7910 | F18: -41060 | G18: -22136 | H18: -45309 | I18: -28098
A19: Gasto financiero neto | D19: =D17+D18 -> -66304 | E19: =E17+E18 -> -848 | F19: =F17+F18 -> -22709 | G19: =G17+G18 -> -12132 | H19: =H17+H18 -> -38535 | I19: =I17+I18 -> -20842
A20: Utilidad antes de impuestos | D20: =D15+D19 -> 569202 | E20: =E15+E19 -> 799967 | F20: =F15+F19 -> 610223 | G20: =G15+G19 -> 444224 | H20: =H15+H19 -> 613318 | I20: =I15+I19 -> 1013418
A21: Gasto por impuesto a las ganancias | B21: 26/27 | D21: -183643 | E21: -247175 | F21: -202878 | G21: -148560 | H21: -198190 | I21: -293511
A22: Utilidad neta y resultado integral del año | D22: =D20+D21 -> 385559 | E22: =E20+E21 -> 552792 | F22: =F20+F21 -> 407345 | G22: =G20+G21 -> 295664 | H22: =H20+H21 -> 415128 | I22: =I20+I21 -> 719907
A24: Ganancia básica por acción común (S/ por acción) | B24: 33/34 | D24: 1.062 | E24: 1.218 | F24: 0.898 | G24: 0.493 | H24: 0.519 | I24: 0.72
A26: Fuente: Estados Financieros Separados Auditados de Compañía Minera Poderosa S.A., cada columna según el reporte del cierre de ese año. 'Otro resultado integral' fue S/ 0 en los seis ejercicios, por lo que la utilidad neta coincide con el total de resultados integrales.
A27: La numeración de notas varía ligeramente entre reportes (p. ej. Ingresos es nota 27 en 2025 y nota 28 en años anteriores); se muestran ambas referencias separadas por '/'.

Sheet ECP
A1: COMPAÑÍA MINERA PODEROSA S.A.
A2: Estado Separado de Cambios en el Patrimonio
A3: Movimiento anual del patrimonio — cifras en miles de soles (S/000)
A5: Concepto | B5: Nota | D5: 2020 | E5: 2021 | F5: 2022 | G5: 2023 | H5: 2024 | I5: 2025
A6: Conciliación del patrimonio total
A7: Patrimonio al inicio del año | D7: 966909 | E7: =D11 -> 1196378 | F7: =E11 -> 1517920 | G7: =F11 -> 1594982 | H7: =G11 -> 1645610 | I7: =H11 -> 1883522
A8: (+) Resultado del ejercicio | D8: 385559 | E8: 552792 | F8: 407345 | G8: 295664 | H8: 415128 | I8: 719907
A9: (-) Dividendos distribuidos | D9: -156090 | E9: -231263 | F9: -330660 | G9: -245036 | H9: -177216 | I9: -396450
A10: (+/-) Otros movimientos netos (dividendos no distribuidos, capitalización de utilidades / reserva legal, ajustes) | D10: =D11-D7-D8-D9 -> 0 | E10: =E11-E7-E8-E9 -> 13 | F10: =F11-F7-F8-F9 -> 377 | G10: =G11-G7-G8-G9 -> 0 | H10: =H11-H7-H8-H9 -> 0 | I10: =I11-I7-I8-I9 -> 0
A11: Patrimonio al final del año | D11: =ESF!D51 -> 1196378 | E11: =ESF!E51 -> 1517920 | F11: =ESF!F51 -> 1594982 | G11: =ESF!G51 -> 1645610 | H11: =ESF!H51 -> 1883522 | I11: =ESF!I51 -> 2206979
A13: Saldos finales por componente del patrimonio (al 31 de diciembre)
A14: Capital emitido | B14: 22/23 | D14: 363000 | E14: 453750 | F14: 453750 | G14: 600000 | H14: 800000 | I14: 1000000
A15: Otras reservas de capital | B15: 23/24 | D15: 72600 | E15: 90750 | F15: 90750 | G15: 120000 | H15: 160000 | I15: 200000
A16: Resultados acumulados | B16: 24/25 | D16: 760778 | E16: 973420 | F16: 1050482 | G16: 925610 | H16: 923522 | I16: 1006979
A17: Total patrimonio (verificación) | D17: =D14+D15+D16 -> 1196378 | E17: =E14+E15+E16 -> 1517920 | F17: =F14+F15+F16 -> 1594982 | G17: =G14+G15+G16 -> 1645610 | H17: =H14+H15+H16 -> 1883522 | I17: =I14+I15+I16 -> 2206979
A18: Diferencia de control (debe ser 0) | D18: =D11-D17 -> 0 | E18: =E11-E17 -> 0 | F18: =F11-F17 -> 0 | G18: =G11-G17 -> 0 | H18: =H11-H17 -> 0 | I18: =I11-I17 -> 0
A20: Número de acciones comunes en circulación (fin de año) | B20: 22/23 | D20: 363000000 | E20: 453750000 | F20: 453750000 | G20: 600000000 | H20: 800000000 | I20: 1000000000
A22: Fuente: Estado Separado de Cambios en el Patrimonio de cada reporte anual auditado. El saldo de patrimonio al 1 de enero de 2020 (S/ 966,909 miles) proviene del Estado Separado de Cambios en el Patrimonio 2021 vs 2020.
A23: 'Otros movimientos netos' agrupa partidas de menor cuantía (dividendos no distribuidos, emisión de acciones por capitalización de resultados y constitución de reserva legal, que son neutrales para el patrimonio total porque mueven saldos entre Capital emitido / Otras reservas y Resultados acumulados) y ajustes menores.

Sheet EFE
A1: COMPAÑÍA MINERA PODEROSA S.A.
A2: Estado Separado de Flujos de Efectivo
A3: Por los años terminados el 31 de diciembre — cifras en miles de soles (S/000)
A5: Concepto | B5: Nota | D5: 2020 | E5: 2021 | F5: 2022 | G5: 2023 | H5: 2024 | I5: 2025
A6: ACTIVIDADES DE OPERACIÓN
A7: Resultado del período (utilidad neta) | D7: 385559 | E7: 552792 | F7: 407345 | G7: 295664 | H7: 415128 | I7: 719907
A8: Cargos (abonos) a resultado que no representan movimiento de efectivo
A9: Depreciación | B9: 12 y 13 | D9: 34688 | E9: 43070 | F9: 46958 | G9: 45573 | H9: 55153 | I9: 64781
A10: Amortización | B10: 14 | D10: 208294 | E10: 210130 | F10: 221408 | G10: 233915 | H10: 298798 | I10: 378608
A11: Provisión para desvalorización de suministros | B11: 9 | I11: 240
A12: Estimación / provisión por deterioro de cuentas por cobrar | B12: 8 | D12: 1398 | E12: 1063 | F12: 411 | G12: 480 | H12: 132 | I12: 76
A13: Recuperación de cuentas incobrables | B13: 8 | F13: -26 | G13: -9 | H13: -32
A14: Provisión por litigios | B14: 19 | D14: 1549 | E14: -1049 | F14: 553 | G14: 657 | H14: 934 | I14: 769
A15: Impuesto a las ganancias diferido | B15: 21/22 | D15: -2650 | E15: -6045 | F15: 6652 | G15: 21793 | H15: 30848 | I15: -28835
A16: Gasto de actualización de la provisión para cierre de mina | B16: 20 | D16: 873 | E16: 877 | F16: 1490 | G16: 3784 | H16: 4924 | I16: 3569
A17: Pérdida en venta de propiedades, planta y equipo | B17: 34/35 | D17: 4846 | E17: 1118 | F17: 52337 | G17: 10125 | H17: 7900 | I17: 150
A18: Ganancia en venta de propiedades, planta y equipo | B18: 34 | I18: -247
A19: Impuesto a las ganancias (gasto del ejercicio) | B19: 26/27 | D19: 186293 | E19: 253220 | F19: 196226 | G19: 126767 | H19: 167342 | I19: 322346
A20: Diferencia en cambio | B20: 5.A/17 | D20: -584 | E20: -5941 | F20: 33899 | G20: 3854 | H20: 4368 | I20: -21980
A21: Costos financieros netos / intereses devengados | B21: 32/33 | D21: 6182 | E21: 5264 | F21: 1512 | G21: 4494 | H21: 29243 | I21: 9413
A22: Cargos y abonos por cambios netos en activos y pasivos
A23: (Aumento) disminución de cuentas por cobrar comerciales | B23: 7 | D23: -3165 | E23: 2605 | F23: -2447 | G23: -1998 | H23: -4665 | I23: -14988
A24: (Aumento) disminución de otras cuentas por cobrar | B24: 8 | D24: 7030 | E24: 96 | F24: -50816 | G24: -26070 | H24: -16591 | I24: 15467
A25: (Aumento) disminución de inventarios | B25: 9 | D25: -5731 | E25: -9772 | F25: -10688 | G25: 2274 | H25: -29349 | I25: -5480
A26: Aumento (disminución) de gastos contratados por anticipado | B26: 10 | D26: -377 | E26: 7950 | F26: 2503 | G26: 987 | H26: 2843 | I26: -4945
A27: Aumento de cuentas por pagar comerciales | B27: 15 | D27: 14628 | E27: 433 | F27: 17352 | G27: 50277 | H27: 11529 | I27: 81727
A28: Aumento (disminución) de otras cuentas por pagar | D28: 52669 | E28: 57757 | F28: -42242 | G28: 39740 | H28: -11936 | I28: 68946
A29: Pago de obligaciones por cierre de unidad minera | B29: 20 | D29: -369 | E29: -5024 | F29: -3002 | G29: -880 | H29: -1159 | I29: -5315
A30: Efectivo generado / provisto por las actividades de operación | D30: =D7+D9+D10+D11+D12+D13+D14+D15+D16+D17+D18+D19+D20+D21+D23+D24+D25+D26+D27+D28+D29 -> 891133 | E30: =E7+E9+E10+E11+E12+E13+E14+E15+E16+E17+E18+E19+E20+E21+E23+E24+E25+E26+E27+E28+E29 -> 1108544 | F30: =F7+F9+F10+F11+F12+F13+F14+F15+F16+F17+F18+F19+F20+F21+F23+F24+F25+F26+F27+F28+F29 -> 879425 | G30: =G7+G9+G10+G11+G12+G13+G14+G15+G16+G17+G18+G19+G20+G21+G23+G24+G25+G26+G27+G28+G29 -> 811427 | H30: =H7+H9+H10+H11+H12+H13+H14+H15+H16+H17+H18+H19+H20+H21+H23+H24+H25+H26+H27+H28+H29 -> 965410 | I30: =I7+I9+I10+I11+I12+I13+I14+I15+I16+I17+I18+I19+I20+I21+I23+I24+I25+I26+I27+I28+I29 -> 1584209
A31: Intereses pagados | D31: -6623 | E31: -6183 | F31: -4881 | G31: -8827 | H31: -11459 | I31: -10225
A32: Impuesto a las ganancias pagado | D32: -166194 | E32: -240251 | F32: -198988 | G32: -183674 | H32: -135635 | I32: -254824
A33: Flujo neto provisto por las actividades de operación | D33: =D30+D31+D32 -> 718316 | E33: =E30+E31+E32 -> 862110 | F33: =F30+F31+F32 -> 675556 | G33: =G30+G31+G32 -> 618926 | H33: =H30+H31+H32 -> 818316 | I33: =I30+I31+I32 -> 1319160
A35: ACTIVIDADES DE INVERSIÓN
A36: Cobranza de depósitos a plazo mayores a 90 días | B36: 6 | G36: 171900
A37: Apertura de depósitos a plazo mayores a 90 días | B37: 6 | F37: -171900
A38: Cobro por venta de propiedades, planta y equipo | B38: 34/35 | D38: 0 | E38: 677 | F38: 651 | G38: 927 | H38: 674
A39: Pago por compra de activos intangibles | B39: 14 | D39: -182497 | E39: -211613 | F39: -316482 | G39: -386261 | H39: -528468 | I39: -541823
A40: Pago por compra de propiedades, planta y equipo | B40: 12/13 | D40: -86788 | E40: -137600 | F40: -175789 | G40: -194014 | H40: -205738 | I40: -199300
A41: Flujo neto utilizado en las actividades de inversión | D41: =D36+D37+D38+D39+D40 -> -269285 | E41: =E36+E37+E38+E39+E40 -> -348536 | F41: =F36+F37+F38+F39+F40 -> -663520 | G41: =G36+G37+G38+G39+G40 -> -407448 | H41: =H36+H37+H38+H39+H40 -> -733532 | I41: =I36+I37+I38+I39+I40 -> -741123
A43: ACTIVIDADES DE FINANCIAMIENTO
...

Sheet Ratios
A1: COMPAÑÍA MINERA PODEROSA S.A.
A2: Indicadores Financieros (Ratios)
A3: Calculados a partir de las hojas ESF, ERI y ECP — enlaces con fórmula (no se modifican a mano)
A5: Concepto | B5: Nota | D5: 2020 | E5: 2021 | F5: 2022 | G5: 2023 | H5: 2024 | I5: 2025
A6: 1. LIQUIDEZ
A7: Razón corriente (veces) | D7: =ESF!D15/ESF!D37 -> 1.3739603 | E7: =ESF!E15/ESF!E37 -> 1.804572 | F7: =ESF!F15/ESF!F37 -> 1.5040665 | G7: =ESF!G15/ESF!G37 -> 1.0866633 | H7: =ESF!H15/ESF!H37 -> 0.81319041 | I7: =ESF!I15/ESF!I37 -> 0.84129771
A8: Prueba ácida (veces) | D8: =(ESF!D15-ESF!D13)/ESF!D37 -> 1.2260208 | E8: =(ESF!E15-ESF!E13)/ESF!E37 -> 1.6549795 | F8: =(ESF!F15-ESF!F13)/ESF!F37 -> 1.3229616 | G8: =(ESF!G15-ESF!G13)/ESF!G37 -> 0.92696067 | H8: =(ESF!H15-ESF!H13)/ESF!H37 -> 0.60573494 | I8: =(ESF!I15-ESF!I13)/ESF!I37 -> 0.70946151
A9: Capital de trabajo (S/000) | D9: =ESF!D15-ESF!D37 -> 126602 | E9: =ESF!E15-ESF!E37 -> 321931 | F9: =ESF!F15-ESF!F37 -> 196344 | G9: =ESF!G15-ESF!G37 -> 37047 | H9: =ESF!H15-ESF!H37 -> -87904 | I9: =ESF!I15-ESF!I37 -> -123820
A11: 2. SOLVENCIA Y APALANCAMIENTO
A12: Pasivo total / Patrimonio (D/E) | D12: =ESF!D45/ESF!D51 -> 0.42791074 | E12: =ESF!E45/ESF!E51 -> 0.36518921 | F12: =ESF!F45/ESF!F51 -> 0.31717913 | G12: =ESF!G45/ESF!G51 -> 0.4143661 | H12: =ESF!H45/ESF!H51 -> 0.35001927 | I12: =ESF!I45/ESF!I51 -> 0.44489096
A13: Pasivo total / Activo total | D13: =ESF!D45/ESF!D24 -> 0.29967611 | E13: =ESF!E45/ESF!E24 -> 0.2675008 | F13: =ESF!F45/ESF!F24 -> 0.24080182 | G13: =ESF!G45/ESF!G24 -> 0.29296948 | H13: =ESF!H45/ESF!H24 -> 0.25926983 | I13: =ESF!I45/ESF!I24 -> 0.30790625
A14: Patrimonio / Activo total (solidez) | D14: =ESF!D51/ESF!D24 -> 0.70032389 | E14: =ESF!E51/ESF!E24 -> 0.7324992 | F14: =ESF!F51/ESF!F24 -> 0.75919818 | G14: =ESF!G51/ESF!G24 -> 0.70703052 | H14: =ESF!H51/ESF!H24 -> 0.74073017 | I14: =ESF!I51/ESF!I24 -> 0.69209375
A15: EBITDA (S/000) = Utilidad operativa + Depreciación + Amortización | D15: =ERI!D15+EFE!D9+EFE!D10 -> 878488 | E15: =ERI!E15+EFE!E9+EFE!E10 -> 1054015 | F15: =ERI!F15+EFE!F9+EFE!F10 -> 901298 | G15: =ERI!G15+EFE!G9+EFE!G10 -> 735844 | H15: =ERI!H15+EFE!H9+EFE!H10 -> 1005804 | I15: =ERI!I15+EFE!I9+EFE!I10 -> 1477649
A16: Margen EBITDA (EBITDA / Ingresos) | D16: =D15/ERI!D6 -> 0.52817207 | E16: =E15/ERI!E6 -> 0.50125621 | F16: =F15/ERI!F6 -> 0.43110218 | G16: =G15/ERI!G6 -> 0.36928651 | H16: =H15/ERI!H6 -> 0.38323044 | I16: =I15/ERI!I6 -> 0.42531269
A18: 3. RENTABILIDAD
A19: Margen bruto | D19: =ERI!D8/ERI!D6 -> 0.47914428 | E19: =ERI!E8/ERI!E6 -> 0.47617093 | F19: =ERI!F8/ERI!F6 -> 0.42344057 | G19: =ERI!G8/ERI!G6 -> 0.33530696 | H19: =ERI!H8/ERI!H6 -> 0.34917001 | I19: =ERI!I8/ERI!I6 -> 0.3943021
A20: Margen operativo | D20: =ERI!D15/ERI!D6 -> 0.38208435 | E20: =ERI!E15/ERI!E6 -> 0.3808423 | F20: =ERI!F15/ERI!F6 -> 0.30273934 | G20: =ERI!G15/ERI!G6 -> 0.22902424 | H20: =ERI!H15/ERI!H6 -> 0.24836838 | I20: =ERI!I15/ERI!I6 -> 0.29769174
A21: Margen neto | D21: =ERI!D22/ERI!D6 -> 0.23180908 | E21: =ERI!E22/ERI!E6 -> 0.2628904 | F21: =ERI!F22/ERI!F6 -> 0.19483824 | G21: =ERI!G22/ERI!G6 -> 0.14838027 | H21: =ERI!H22/ERI!H6 -> 0.15817166 | I21: =ERI!I22/ERI!I6 -> 0.20721131
A22: ROE (Utilidad neta / Patrimonio, fin de año) | D22: =ERI!D22/ESF!D51 -> 0.32227189 | E22: =ERI!E22/ESF!E51 -> 0.3641773 | F22: =ERI!F22/ESF!F51 -> 0.2553916 | G22: =ERI!G22/ESF!G51 -> 0.17966833 | H22: =ERI!H22/ESF!H51 -> 0.22039987 | I22: =ERI!I22/ESF!I51 -> 0.32619567
A23: ROA (Utilidad neta / Activo total, fin de año) | D23: =ERI!D22/ESF!D24 -> 0.2256947 | E23: =ERI!E22/ESF!E24 -> 0.26675958 | F23: =ERI!F22/ESF!F24 -> 0.19389284 | G23: =ERI!G22/ESF!G24 -> 0.12703099 | H23: =ERI!H22/ESF!H24 -> 0.16325683 | I23: =ERI!I22/ESF!I24 -> 0.22575799
A25: 4. EFICIENCIA / GESTIÓN
A26: Rotación de activos (veces) = Ingresos / Activo total | D26: =ERI!D6/ESF!D24 -> 0.97362322 | E26: =ERI!E6/ESF!E24 -> 1.0147178 | F26: =ERI!F6/ESF!F24 -> 0.99514774 | G26: =ERI!G6/ESF!G24 -> 0.85611784 | H26: =ERI!H6/ESF!H24 -> 1.0321497 | I26: =ERI!I6/ESF!I24 -> 1.0895061
A27: Rotación de inventarios (veces) = |Costo de ventas| / Inventario | D27: =ABS(ERI!D7)/ESF!D13 -> 17.297321 | E27: =ABS(ERI!E7)/ESF!E13 -> 18.402165 | F27: =ABS(ERI!F7)/ESF!F13 -> 17.087251 | G27: =ABS(ERI!G7)/ESF!G13 -> 19.400527 | H27: =ABS(ERI!H7)/ESF!H13 -> 17.497926 | I27: =ABS(ERI!I7)/ESF!I13 -> 20.458638
A28: Días de inventario (365 / rotación) | D28: =365/(ABS(ERI!D7)/ESF!D13) -> 21.101534 | E28: =365/(ABS(ERI!E7)/ESF!E13) -> 19.834623 | F28: =365/(ABS(ERI!F7)/ESF!F13) -> 21.360956 | G28: =365/(ABS(ERI!G7)/ESF!G13) -> 18.813922 | H28: =365/(ABS(ERI!H7)/ESF!H13) -> 20.859615 | I28: =365/(ABS(ERI!I7)/ESF!I13) -> 17.840875
A30: 5. POR ACCIÓN
A31: Utilidad neta por acción (S/, básica) | D31: =ERI!D24 -> 1.062 | E31: =ERI!E24 -> 1.218 | F31: =ERI!F24 -> 0.898 | G31: =ERI!G24 -> 0.493 | H31: =ERI!H24 -> 0.519 | I31: =ERI!I24 -> 0.72
A32: Valor patrimonial por acción (S/) = Patrimonio / N° acciones fin de año | D32: =ESF!D51/ECP!D20 -> 0.0032958072 | E32: =ESF!E51/ECP!E20 -> 0.0033452782 | F32: =ESF!F51/ECP!F20 -> 0.0035151118 | G32: =ESF!G51/ECP!G20 -> 0.0027426833 | H32: =ESF!H51/ECP!H20 -> 0.0023544025 | I32: =ESF!I51/ECP!I20 -> 0.002206979
A33: Dividendo pagado por acción (S/, aprox. sobre acciones fin de año) | D33: =-ECP!D9/ECP!D20 -> 0.00043 | E33: =-ECP!E9/ECP!E20 -> 0.00050967052 | F33: =-ECP!F9/ECP!F20 -> 0.00072872727 | G33: =-ECP!G9/ECP!G20 -> 0.00040839333 | H33: =-ECP!H9/ECP!H20 -> 0.00022152 | I33: =-ECP!I9/ECP!I20 -> 0.00039645
A36: Todos los indicadores de esta hoja se calculan con fórmulas que enlazan a las hojas ESF, ERI y ECP; no se ha digitado ningún número directamente en esta hoja.
A37: EBITDA aproximado = Utilidad operativa + Depreciación + Amortización del Estado de Flujos de Efectivo (no incluye ajustes por partidas no recurrentes distintas a D&A).
A38: El dividendo por acción es una aproximación porque el número de acciones en circulación cambió durante algunos ejercicios (aumentos de capital por capitalización de utilidades); ver hoja ECP para el detalle de la fecha de cada emisión.

Sheet Cap3_Base2019
A1: COMPAÑÍA MINERA PODEROSA S.A.
A2: Saldos de apertura al 1 de enero de 2020 (= cierre auditado al 31.12.2019)
A3: Insumo exclusivo para calcular los saldos PROMEDIO de 2020 en la hoja Cap3_Ficha_Promedio
A5: Concepto | B5: Nota | C5: 2019
A6: Inventarios | B6: 9 | C6: 44353
A7: Cuentas por cobrar comerciales | B7: 7 | C7: 9622
A8: Otras cuentas por cobrar | B8: 8 | C8: 23718
A9: Cuentas por pagar comerciales | B9: 15 | C9: 70981
A11: Fuente: Compañía Minera Poderosa S.A., Memoria Anual / Informe de Sostenibilidad 2020, Estado Separado de Situación Financiera al 31 de diciembre de 2020 y de 2019 (columna comparativa 2019).

Sheet Cap3_Ficha_Promedio
A1: COMPAÑÍA MINERA PODEROSA S.A.
A2: Capítulo 3 — Ficha de Registro de Indicadores (saldos PROMEDIO)
A3: PPI, PPC, PPP, CCE, ROA y ROE — período 2020-2025 — base de 360 días
A5: Concepto | B5: Nota | D5: 2020 | E5: 2021 | F5: 2022 | G5: 2023 | H5: 2024 | I5: 2025
A6: 1. INVENTARIO (S/000)
A7: Inventario al cierre del año anterior | B7: 9 | D7: =Cap3_Base2019!$C$6 -> 44353 | E7: =ESF!D13 -> 50084 | F7: =ESF!E13 -> 59856 | G7: =ESF!F13 -> 70544 | H7: =ESF!G13 -> 68270 | I7: =ESF!H13 -> 97619
A8: Inventario al cierre del año | B8: 9 | D8: =ESF!D13 -> 50084 | E8: =ESF!E13 -> 59856 | F8: =ESF!F13 -> 70544 | G8: =ESF!G13 -> 68270 | H8: =ESF!H13 -> 97619 | I8: =ESF!I13 -> 102859
A9: Inventario PROMEDIO | D9: =AVERAGE(D7:D8) -> 47218.5 | E9: =AVERAGE(E7:E8) -> 54970 | F9: =AVERAGE(F7:F8) -> 65200 | G9: =AVERAGE(G7:G8) -> 69407 | H9: =AVERAGE(H7:H8) -> 82944.5 | I9: =AVERAGE(I7:I8) -> 100239
A11: 2. CUENTAS POR COBRAR (S/000) — comerciales + otras, corrientes
A12: Cuentas por cobrar comerciales (año anterior) | B12: 7 | D12: =Cap3_Base2019!$C$7 -> 9622 | E12: =ESF!D10 -> 12787 | F12: =ESF!E10 -> 10183 | G12: =ESF!F10 -> 12630 | H12: =ESF!G10 -> 14628 | I12: =ESF!H10 -> 19293
A13: Otras cuentas por cobrar (año anterior) | B13: 8 | D13: =Cap3_Base2019!$C$8 -> 23718 | E13: =ESF!D11 -> 16688 | F13: =ESF!E11 -> 16592 | G13: =ESF!F11 -> 62109 | H13: =ESF!G11 -> 87810 | I13: =ESF!H11 -> 104314
A14: Total cuentas por cobrar (año anterior) | D14: =D12+D13 -> 33340 | E14: =E12+E13 -> 29475 | F14: =F12+F13 -> 26775 | G14: =G12+G13 -> 74739 | H14: =H12+H13 -> 102438 | I14: =I12+I13 -> 123607
A15: Cuentas por cobrar comerciales (año actual) | B15: 7 | D15: =ESF!D10 -> 12787 | E15: =ESF!E10 -> 10183 | F15: =ESF!F10 -> 12630 | G15: =ESF!G10 -> 14628 | H15: =ESF!H10 -> 19293 | I15: =ESF!I10 -> 34281
A16: Otras cuentas por cobrar (año actual) | B16: 8 | D16: =ESF!D11 -> 16688 | E16: =ESF!E11 -> 16592 | F16: =ESF!F11 -> 62109 | G16: =ESF!G11 -> 87810 | H16: =ESF!H11 -> 104314 | I16: =ESF!I11 -> 83432
A17: Total cuentas por cobrar (año actual) | D17: =D15+D16 -> 29475 | E17: =E15+E16 -> 26775 | F17: =F15+F16 -> 74739 | G17: =G15+G16 -> 102438 | H17: =H15+H16 -> 123607 | I17: =I15+I16 -> 117713
A18: Cuentas por cobrar PROMEDIO | D18: =AVERAGE(D14,D17) -> 31407.5 | E18: =AVERAGE(E14,E17) -> 28125 | F18: =AVERAGE(F14,F17) -> 50757 | G18: =AVERAGE(G14,G17) -> 88588.5 | H18: =AVERAGE(H14,H17) -> 113022.5 | I18: =AVERAGE(I14,I17) -> 120660
A20: 3. CUENTAS POR PAGAR COMERCIALES (S/000)
A21: Cuentas por pagar comerciales (año anterior) | B21: 15 | D21: =Cap3_Base2019!$C$9 -> 70981 | E21: =ESF!D28 -> 85609 | F21: =ESF!E28 -> 86042 | G21: =ESF!F28 -> 103394 | H21: =ESF!G28 -> 210432 | I21: =ESF!H28 -> 221961
A22: Cuentas por pagar comerciales (año actual) | B22: 15 | D22: =ESF!D28 -> 85609 | E22: =ESF!E28 -> 86042 | F22: =ESF!F28 -> 103394 | G22: =ESF!G28 -> 210432 | H22: =ESF!H28 -> 221961 | I22: =ESF!I28 -> 303688
A23: Cuentas por pagar PROMEDIO | D23: =AVERAGE(D21:D22) -> 78295 | E23: =AVERAGE(E21:E22) -> 85825.5 | F23: =AVERAGE(F21:F22) -> 94718 | G23: =AVERAGE(G21:G22) -> 156913 | H23: =AVERAGE(H21:H22) -> 216196.5 | I23: =AVERAGE(I21:I22) -> 262824.5
A25: 4. VARIABLES DEL ESTADO DE RESULTADOS Y DEL BALANCE (S/000)
A26: Costo de ventas del año (valor absoluto) | B26: 28/29 | D26: =ABS(ERI!D7) -> 866319 | E26: =ABS(ERI!E7) -> 1101480 | F26: =ABS(ERI!F7) -> 1205403 | G26: =ABS(ERI!G7) -> 1324474 | H26: =ABS(ERI!H7) -> 1708130 | I26: =ABS(ERI!I7) -> 2104355
A27: Ventas netas del año | B27: 27/28 | D27: =ERI!D6 -> 1663261 | E27: =ERI!E6 -> 2102747 | F27: =ERI!F6 -> 2090683 | G27: =ERI!G6 -> 1992610 | H27: =ERI!H6 -> 2624541 | I27: =ERI!I6 -> 3474265
A28: Utilidad neta del año | D28: =ERI!D22 -> 385559 | E28: =ERI!E22 -> 552792 | F28: =ERI!F22 -> 407345 | G28: =ERI!G22 -> 295664 | H28: =ERI!H22 -> 415128 | I28: =ERI!I22 -> 719907
A29: Activo total (saldo de cierre) | D29: =ESF!D24 -> 1708321 | E29: =ESF!E24 -> 2072248 | F29: =ESF!F24 -> 2100877 | G29: =ESF!G24 -> 2327495 | H29: =ESF!H24 -> 2542791 | I29: =ESF!I24 -> 3188844
A30: Patrimonio total (saldo de cierre) | D30: =ESF!D51 -> 1196378 | E30: =ESF!E51 -> 1517920 | F30: =ESF!F51 -> 1594982 | G30: =ESF!G51 -> 1645610 | H30: =ESF!H51 -> 1883522 | I30: =ESF!I51 -> 2206979
A32: 5. INDICADORES — CAPITAL DE TRABAJO Y RENTABILIDAD
A33: PPI — Período Promedio de Inventarios (días) | D33: =D9/D26*360 -> 19.62171 | E33: =E9/E26*360 -> 17.966009 | F33: =F9/F26*360 -> 19.472326 | G33: =G9/G26*360 -> 18.86524 | H33: =H9/H26*360 -> 17.481117 | I33: =I9/I26*360 -> 17.148266
A34: PPC — Período Promedio de Cobro (días) | D34: =D18/D27*360 -> 6.7979109 | E34: =E18/E27*360 -> 4.8151299 | F34: =F18/F27*360 -> 8.7399764 | G34: =G18/G27*360 -> 16.005069 | H34: =H18/H27*360 -> 15.502939 | I34: =I18/I27*360 -> 12.502673
A35: PPP — Período Promedio de Pago (días) | D35: =D23/D26*360 -> 32.53559 | E35: =E23/E26*360 -> 28.050605 | F35: =F23/F26*360 -> 28.288033 | G35: =G23/G26*360 -> 42.649897 | H35: =H23/H26*360 -> 45.564881 | I35: =I23/I26*360 -> 44.962385
A36: CCE — Ciclo de Conversión de Efectivo (días) = PPI+PPC-PPP | D36: =D33+D34-D35 -> -6.1159696 | E36: =E33+E34-E35 -> -5.2694653 | F36: =F33+F34-F35 -> -0.075730916 | G36: =G33+G34-G35 -> -7.7795884 | H36: =H33+H34-H35 -> -12.580825 | I36: =I33+I34-I35 -> -15.311446
A38: ROA — Utilidad neta / Activo total × 100 (%) | D38: =D28/D29*100 -> 22.56947 | E38: =E28/E29*100 -> 26.675958 | F38: =F28/F29*100 -> 19.389284 | G38: =G28/G29*100 -> 12.703099 | H38: =H28/H29*100 -> 16.325683 | I38: =I28/I29*100 -> 22.575799
A39: ROE — Utilidad neta / Patrimonio total × 100 (%) | D39: =D28/D30*100 -> 32.227189 | E39: =E28/E30*100 -> 36.41773 | F39: =F28/F30*100 -> 25.53916 | G39: =G28/G30*100 -> 17.966833 | H39: =H28/H30*100 -> 22.039987 | I39: =I28/I30*100 -> 32.619567
A41: Metodología: saldo PROMEDIO = (saldo al cierre del año anterior + saldo al cierre del año actual) / 2, conforme a Ross, Westerfield y Jordan (2019). Los saldos de cierre de cada año se enlazan directamente a las hojas ESF y ERI de este mismo libro; el saldo de apertura de 2020 (cierre 2019) se toma de la hoja Cap3_Base2019. Base de 360 días, tal como especifica el capítulo 2.3.4 de la tesis.
A42: Celdas amarillas = los 4 indicadores de la variable independiente (Gestión del capital de trabajo). Celdas verdes = los 2 indicadores de la variable dependiente (Rentabilidad).

Sheet Cap3_Ficha_Cierre
A1: COMPAÑÍA MINERA PODEROSA S.A.
A2: Capítulo 3 — Ficha de Registro de Indicadores (saldos de CIERRE)
A3: Criterio alternativo (sin promediar) — coincide con los valores 2023 y 2025 ya verificados en el avance
A5: Concepto | B5: Nota | D5: 2020 | E5: 2021 | F5: 2022 | G5: 2023 | H5: 2024 | I5: 2025
A6: VARIABLES BASE (S/000)
A7: Inventario (saldo de cierre) | B7: 9 | D7: =ESF!D13 -> 50084 | E7: =ESF!E13 -> 59856 | F7: =ESF!F13 -> 70544 | G7: =ESF!G13 -> 68270 | H7: =ESF!H13 -> 97619 | I7: =ESF!I13 -> 102859
A8: Cuentas por cobrar totales (saldo de cierre) | B8: 7/8 | D8: =ESF!D10+ESF!D11 -> 29475 | E8: =ESF!E10+ESF!E11 -> 26775 | F8: =ESF!F10+ESF!F11 -> 74739 | G8: =ESF!G10+ESF!G11 -> 102438 | H8: =ESF!H10+ESF!H11 -> 123607 | I8: =ESF!I10+ESF!I11 -> 117713
A9: Cuentas por pagar comerciales (saldo de cierre) | B9: 15 | D9: =ESF!D28 -> 85609 | E9: =ESF!E28 -> 86042 | F9: =ESF!F28 -> 103394 | G9: =ESF!G28 -> 210432 | H9: =ESF!H28 -> 221961 | I9: =ESF!I28 -> 303688
A10: Costo de ventas del año (valor absoluto) | B10: 28/29 | D10: =ABS(ERI!D7) -> 866319 | E10: =ABS(ERI!E7) -> 1101480 | F10: =ABS(ERI!F7) -> 1205403 | G10: =ABS(ERI!G7) -> 1324474 | H10: =ABS(ERI!H7) -> 1708130 | I10: =ABS(ERI!I7) -> 2104355
A11: Ventas netas del año | B11: 27/28 | D11: =ERI!D6 -> 1663261 | E11: =ERI!E6 -> 2102747 | F11: =ERI!F6 -> 2090683 | G11: =ERI!G6 -> 1992610 | H11: =ERI!H6 -> 2624541 | I11: =ERI!I6 -> 3474265
A12: Utilidad neta del año | D12: =ERI!D22 -> 385559 | E12: =ERI!E22 -> 552792 | F12: =ERI!F22 -> 407345 | G12: =ERI!G22 -> 295664 | H12: =ERI!H22 -> 415128 | I12: =ERI!I22 -> 719907
A13: Activo total (saldo de cierre) | D13: =ESF!D24 -> 1708321 | E13: =ESF!E24 -> 2072248 | F13: =ESF!F24 -> 2100877 | G13: =ESF!G24 -> 2327495 | H13: =ESF!H24 -> 2542791 | I13: =ESF!I24 -> 3188844
A14: Patrimonio total (saldo de cierre) | D14: =ESF!D51 -> 1196378 | E14: =ESF!E51 -> 1517920 | F14: =ESF!F51 -> 1594982 | G14: =ESF!G51 -> 1645610 | H14: =ESF!H51 -> 1883522 | I14: =ESF!I51 -> 2206979
A16: INDICADORES
A17: PPI (días) | D17: =D7/D10*360 -> 20.812472 | E17: =E7/E10*360 -> 19.562915 | F17: =F7/F10*360 -> 21.06834 | G17: =G7/G10*360 -> 18.556197 | H17: =H7/H10*360 -> 20.573867 | I17: =I7/I10*360 -> 17.59648
A18: PPC (días) | D18: =D8/D11*360 -> 6.3796361 | E18: =E8/E11*360 -> 4.5840037 | F18: =F8/F11*360 -> 12.869498 | G18: =G8/G11*360 -> 18.507224 | H18: =H8/H11*360 -> 16.954782 | I18: =I8/I11*360 -> 12.197308
A19: PPP (días) | D19: =D9/D10*360 -> 35.574933 | E19: =E9/E10*360 -> 28.121364 | F19: =F9/F10*360 -> 30.879167 | G19: =G9/G10*360 -> 57.196683 | H19: =H9/H10*360 -> 46.779788 | I19: =I9/I10*360 -> 51.953059
A20: CCE (días) = PPI+PPC-PPP | D20: =D17+D18-D19 -> -8.3828243 | E20: =E17+E18-E19 -> -3.9744449 | F20: =F17+F18-F19 -> 3.0586709 | G20: =G17+G18-G19 -> -20.133263 | H20: =H17+H18-H19 -> -9.2511393 | I20: =I17+I18-I19 -> -22.159272
A22: ROA (%) | D22: =D12/D13*100 -> 22.56947 | E22: =E12/E13*100 -> 26.675958 | F22: =F12/F13*100 -> 19.389284 | G22: =G12/G13*100 -> 12.703099 | H22: =H12/H13*100 -> 16.325683 | I22: =I12/I13*100 -> 22.575799
A23: ROE (%) | D23: =D12/D14*100 -> 32.227189 | E23: =E12/E14*100 -> 36.41773 | F23: =F12/F14*100 -> 25.53916 | G23: =G12/G14*100 -> 17.966833 | H23: =H12/H14*100 -> 22.039987 | I23: =I12/I14*100 -> 32.619567
A25: Este criterio NO promedia (usa directamente el saldo al 31 de diciembre de cada año). Se incluye porque coincide exactamente con los valores 2023 y 2025 ya verificados en el avance de la ficha de registro (apartado 2.3.2 de la tesis). Se recomienda usar un solo criterio en el documento final — ver nota en el Capítulo 3 (Word) sobre por qué se sugiere el criterio de saldo PROMEDIO (hoja Cap3_Ficha_Promedio).

Sheet Cap3_Descriptivos
A1: COMPAÑÍA MINERA PODEROSA S.A.
A2: Capítulo 3 — Estadística Descriptiva de los Indicadores (2020-2025, n = 6)
A3: Calculada sobre la ficha de saldos PROMEDIO (hoja Cap3_Ficha_Promedio)
A5: Indicador | B5: n | C5: Media | D5: Desv. Estándar | E5: Mínimo | F5: Máximo | G5: CV (%)
A6: PPI (días) | B6: =COUNT(Cap3_Ficha_Promedio!D33:I33) -> 6 | C6: =AVERAGE(Cap3_Ficha_Promedio!D33:I33) -> 18.425778 | D6: =STDEV(Cap3_Ficha_Promedio!D33:I33) -> 1.0444568 | E6: =MIN(Cap3_Ficha_Promedio!D33:I33) -> 17.148266 | F6: =MAX(Cap3_Ficha_Promedio!D33:I33) -> 19.62171 | G6: =ABS(D6/C6)*100 -> 5.6684544
A7: PPC (días) | B7: =COUNT(Cap3_Ficha_Promedio!D34:I34) -> 6 | C7: =AVERAGE(Cap3_Ficha_Promedio!D34:I34) -> 10.727283 | D7: =STDEV(Cap3_Ficha_Promedio!D34:I34) -> 4.6509533 | E7: =MIN(Cap3_Ficha_Promedio!D34:I34) -> 4.8151299 | F7: =MAX(Cap3_Ficha_Promedio!D34:I34) -> 16.005069 | G7: =ABS(D7/C7)*100 -> 43.356303
A8: PPP (días) | B8: =COUNT(Cap3_Ficha_Promedio!D35:I35) -> 6 | C8: =AVERAGE(Cap3_Ficha_Promedio!D35:I35) -> 37.008565 | D8: =STDEV(Cap3_Ficha_Promedio!D35:I35) -> 8.3017909 | E8: =MIN(Cap3_Ficha_Promedio!D35:I35) -> 28.050605 | F8: =MAX(Cap3_Ficha_Promedio!D35:I35) -> 45.564881 | G8: =ABS(D8/C8)*100 -> 22.43208
A9: CCE (días) | B9: =COUNT(Cap3_Ficha_Promedio!D36:I36) -> 6 | C9: =AVERAGE(Cap3_Ficha_Promedio!D36:I36) -> -7.8555041 | D9: =STDEV(Cap3_Ficha_Promedio!D36:I36) -> 5.4436005 | E9: =MIN(Cap3_Ficha_Promedio!D36:I36) -> -15.311446 | F9: =MAX(Cap3_Ficha_Promedio!D36:I36) -> -0.075730916 | G9: =ABS(D9/C9)*100 -> 69.296641
A10: ROA (%) | B10: =COUNT(Cap3_Ficha_Promedio!D38:I38) -> 6 | C10: =AVERAGE(Cap3_Ficha_Promedio!D38:I38) -> 20.039882 | D10: =STDEV(Cap3_Ficha_Promedio!D38:I38) -> 4.9982822 | E10: =MIN(Cap3_Ficha_Promedio!D38:I38) -> 12.703099 | F10: =MAX(Cap3_Ficha_Promedio!D38:I38) -> 26.675958 | G10: =ABS(D10/C10)*100 -> 24.941675
A11: ROE (%) | B11: =COUNT(Cap3_Ficha_Promedio!D39:I39) -> 6 | C11: =AVERAGE(Cap3_Ficha_Promedio!D39:I39) -> 27.801744 | D11: =STDEV(Cap3_Ficha_Promedio!D39:I39) -> 7.1003352 | E11: =MIN(Cap3_Ficha_Promedio!D39:I39) -> 17.966833 | F11: =MAX(Cap3_Ficha_Promedio!D39:I39) -> 36.41773 | G11: =ABS(D11/C11)*100 -> 25.539172
A13: n = COUNT(); Media = AVERAGE(); Desviación estándar muestral = STDEV(); CV = |Desv. Estándar / Media| × 100.
A14: El CV del CCE es numéricamente elevado porque su media está muy próxima a cero (ver Capítulo 3, Word, nota de la Tabla 3): para esa fila es preferible interpretar la desviación estándar y el rango, no el CV.

Sheet Cap3_Normalidad
A1: COMPAÑÍA MINERA PODEROSA S.A.
A2: Capítulo 3 — Prueba de Normalidad de Shapiro-Wilk (n = 6, α = 0.05)
A3: H0: la serie proviene de una distribución normal — calculado con Python scipy.stats.shapiro()
A5: Indicador | B5: Estadístico W | C5: Valor p | D5: Decisión (α = 0.05)
A6: PPI | B6: 0.9106 | C6: 0.4405 | D6: =IF(C6>0.05,"No se rechaza H0 -> distribución normal","Se rechaza H0 -> NO normal") -> No se rechaza H0 -> distribución normal
A7: PPC | B7: 0.9191 | C7: 0.4991 | D7: =IF(C7>0.05,"No se rechaza H0 -> distribución normal","Se rechaza H0 -> NO normal") -> No se rechaza H0 -> distribución normal
A8: PPP | B8: 0.8224 | C8: 0.0926 | D8: =IF(C8>0.05,"No se rechaza H0 -> distribución normal","Se rechaza H0 -> NO normal") -> No se rechaza H0 -> distribución normal
A9: CCE | B9: 0.9711 | C9: 0.9 | D9: =IF(C9>0.05,"No se rechaza H0 -> distribución normal","Se rechaza H0 -> NO normal") -> No se rechaza H0 -> distribución normal
A10: ROA | B10: 0.9721 | C10: 0.906 | D10: =IF(C10>0.05,"No se rechaza H0 -> distribución normal","Se rechaza H0 -> NO normal") -> No se rechaza H0 -> distribución normal
A11: ROE | B11: 0.9437 | C11: 0.6892 | D11: =IF(C11>0.05,"No se rechaza H0 -> distribución normal","Se rechaza H0 -> NO normal") -> No se rechaza H0 -> distribución normal
A13: El estadístico W y el valor p de Shapiro-Wilk NO tienen una función nativa equivalente en Excel/LibreOffice Calc, por lo que se registran aquí como datos de entrada (en azul), trazables al script 'analisis_tesis.py' (función scipy.stats.shapiro) entregado como Anexo A del Capítulo 3 y reproducible por cualquier tercero a partir de la hoja Cap3_Ficha_Promedio.
A14: Como las 6 series no rechazan H0 (p > 0.05 en todos los casos), en la hoja Cap3_Correlaciones se aplica el coeficiente de correlación de Pearson, conforme al criterio de decisión del capítulo 2.4 de la tesis.

Sheet Cap3_Correlaciones
A1: COMPAÑÍA MINERA PODEROSA S.A.
A2: Capítulo 3 — Correlación de Pearson entre Capital de Trabajo y Rentabilidad (n = 6, α = 0.05)
A3: r = PEARSON(); t = r·√(n-2)/√(1-r²); p = TDIST(|t|, n-2, 2 colas) — enlazado a Cap3_Ficha_Promedio
A5: Hipótesis | B5: Var. 1 | C5: Var. 2 | D5: r de Pearson | E5: t | F5: g.l. | G5: Valor p (bilateral) | H5: Magnitud (Cohen) | I5: Decisión (α=0.05)
A6: HE1 | B6: PPI | C6: ROA | D6: =PEARSON(Cap3_Ficha_Promedio!D33:I33,Cap3_Ficha_Promedio!D38:I38) -> -0.14029212 | E6: =D6*SQRT(F6)/SQRT(1-D6^2) -> -0.2833869 | F6: =COUNT(Cap3_Ficha_Promedio!D33:I33)-2 -> 4 | G6: =TDIST(ABS(E6),F6,2) -> 0.79094242 | H6: =IF(ABS(D6)<0.1,"Trivial/nula",IF(ABS(D6)<0.3,"Débil",IF(ABS(D6)<0.5,"Moderada","Fuerte"))) -> Débil | I6: =IF(G6<0.05,"Se rechaza H0 (significativa)","No se rechaza H0") -> No se rechaza H0
A7: HE1 | B7: PPI | C7: ROE | D7: =PEARSON(Cap3_Ficha_Promedio!D33:I33,Cap3_Ficha_Promedio!D39:I39) -> -0.16371966 | E7: =D7*SQRT(F7)/SQRT(1-D7^2) -> -0.33191791 | F7: =COUNT(Cap3_Ficha_Promedio!D33:I33)-2 -> 4 | G7: =TDIST(ABS(E7),F7,2) -> 0.7566147 | H7: =IF(ABS(D7)<0.1,"Trivial/nula",IF(ABS(D7)<0.3,"Débil",IF(ABS(D7)<0.5,"Moderada","Fuerte"))) -> Débil | I7: =IF(G7<0.05,"Se rechaza H0 (significativa)","No se rechaza H0") -> No se rechaza H0
A8: HE2 | B8: PPC | C8: ROA | D8: =PEARSON(Cap3_Ficha_Promedio!D34:I34,Cap3_Ficha_Promedio!D38:I38) -> -0.85893811 | E8: =D8*SQRT(F8)/SQRT(1-D8^2) -> -3.3547067 | F8: =COUNT(Cap3_Ficha_Promedio!D34:I34)-2 -> 4 | G8: =TDIST(ABS(E8),F8,2) -> 0.028444227 | H8: =IF(ABS(D8)<0.1,"Trivial/nula",IF(ABS(D8)<0.3,"Débil",IF(ABS(D8)<0.5,"Moderada","Fuerte"))) -> Fuerte | I8: =IF(G8<0.05,"Se rechaza H0 (significativa)","No se rechaza H0") -> Se rechaza H0 (significativa)
A9: HE2 | B9: PPC | C9: ROE | D9: =PEARSON(Cap3_Ficha_Promedio!D34:I34,Cap3_Ficha_Promedio!D39:I39) -> -0.81579305 | E9: =D9*SQRT(F9)/SQRT(1-D9^2) -> -2.8211347 | F9: =COUNT(Cap3_Ficha_Promedio!D34:I34)-2 -> 4 | G9: =TDIST(ABS(E9),F9,2) -> 0.047773025 | H9: =IF(ABS(D9)<0.1,"Trivial/nula",IF(ABS(D9)<0.3,"Débil",IF(ABS(D9)<0.5,"Moderada","Fuerte"))) -> Fuerte | I9: =IF(G9<0.05,"Se rechaza H0 (significativa)","No se rechaza H0") -> Se rechaza H0 (significativa)
A10: HE3 | B10: PPP | C10: ROA | D10: =PEARSON(Cap3_Ficha_Promedio!D35:I35,Cap3_Ficha_Promedio!D38:I38) -> -0.56916091 | E10: =D10*SQRT(F10)/SQRT(1-D10^2) -> -1.3844388 | F10: =COUNT(Cap3_Ficha_Promedio!D35:I35)-2 -> 4 | G10: =TDIST(ABS(E10),F10,2) -> 0.23844681 | H10: =IF(ABS(D10)<0.1,"Trivial/nula",IF(ABS(D10)<0.3,"Débil",IF(ABS(D10)<0.5,"Moderada","Fuerte"))) -> Fuerte | I10: =IF(G10<0.05,"Se rechaza H0 (significativa)","No se rechaza H0") -> No se rechaza H0
A11: HE3 | B11: PPP | C11: ROE | D11: =PEARSON(Cap3_Ficha_Promedio!D35:I35,Cap3_Ficha_Promedio!D39:I39) -> -0.48759258 | E11: =D11*SQRT(F11)/SQRT(1-D11^2) -> -1.1169594 | F11: =COUNT(Cap3_Ficha_Promedio!D35:I35)-2 -> 4 | G11: =TDIST(ABS(E11),F11,2) -> 0.32657285 | H11: =IF(ABS(D11)<0.1,"Trivial/nula",IF(ABS(D11)<0.3,"Débil",IF(ABS(D11)<0.5,"Moderada","Fuerte"))) -> Moderada | I11: =IF(G11<0.05,"Se rechaza H0 (significativa)","No se rechaza H0") -> No se rechaza H0
A12: HG | B12: CCE | C12: ROA | D12: =PEARSON(Cap3_Ficha_Promedio!D36:I36,Cap3_Ficha_Promedio!D38:I38) -> 0.10721667 | E12: =D12*SQRT(F12)/SQRT(1-D12^2) -> 0.21567657 | F12: =COUNT(Cap3_Ficha_Promedio!D36:I36)-2 -> 4 | G12: =TDIST(ABS(E12),F12,2) -> 0.83979124 | H12: =IF(ABS(D12)<0.1,"Trivial/nula",IF(ABS(D12)<0.3,"Débil",IF(ABS(D12)<0.5,"Moderada","Fuerte"))) -> Débil | I12: =IF(G12<0.05,"Se rechaza H0 (significativa)","No se rechaza H0") -> No se rechaza H0
A13: HG | B13: CCE | C13: ROE | D13: =PEARSON(Cap3_Ficha_Promedio!D36:I36,Cap3_Ficha_Promedio!D39:I39) -> 0.015188132 | E13: =D13*SQRT(F13)/SQRT(1-D13^2) -> 0.030379768 | F13: =COUNT(Cap3_Ficha_Promedio!D36:I36)-2 -> 4 | G13: =TDIST(ABS(E13),F13,2) -> 0.97721955 | H13: =IF(ABS(D13)<0.1,"Trivial/nula",IF(ABS(D13)<0.3,"Débil",IF(ABS(D13)<0.5,"Moderada","Fuerte"))) -> Trivial/nula | I13: =IF(G13<0.05,"Se rechaza H0 (significativa)","No se rechaza H0") -> No se rechaza H0
A15: r de Pearson y el valor p se calculan con fórmulas nativas de Excel/LibreOffice (PEARSON, TDIST) enlazadas en vivo a la hoja Cap3_Ficha_Promedio: si se corrige o actualiza cualquier cifra fuente en ESF o ERI, esta tabla se recalcula automáticamente. Los valores de r y p coinciden con los obtenidos en Python (scipy.stats.pearsonr) reportados en el Capítulo 3 del informe.
A16: H0: no existe correlación lineal entre las dos variables (ρ = 0). g.l. = grados de libertad = n - 2 = 4. Magnitud según los criterios de Cohen (1988): <0.10 trivial, 0.10-0.29 débil, 0.30-0.49 moderada, ≥0.50 fuerte.
