Workbook

Sheet Ficha de Registro de Datos
A1: FICHA DE REGISTRO DE DATOS
A2: Instrumento de recolección de datos — Técnica: Análisis documental
A4: Investigador(a): | B4: Eder Cedano B.
A5: Universidad: | B5: Universidad Privada del Norte (UPN)
A6: Título de la investigación: | B6: Gestión del Capital de Trabajo y su Relación con la Rentabilidad de Compañía Minera Poderosa S.A., 2020-2025
A7: Empresa analizada: | B7: Compañía Minera Poderosa S.A.
A8: Periodo de análisis: | B8: 2020 - 2025 (anual de cada ejercicio)
A9: Moneda / unidad: | B9: Soles (S/), expresadas en miles (S/000)
A10: Fuente de información: | B10: Estados Financieros Separados Auditados de Compañía Minera Poderosa S.A. (SMV)
A11: Criterio de cálculo: | B11: Saldo PROMEDIO = (saldo de cierre del año anterior + saldo de cierre del año actual) / 2, conforme a Ross, Westerfield & Jordan (2019). Base de 360 días.
A12: Diseño metodológico: | B12: Correlacional, no experimental, longitudinal (Hernández-Sampieri & Mendoza, 2018)
A14: Leyenda: Celdas amarillas = dato extraído directamente de los Estados Financieros Auditados | Celdas verdes = indicador calculado automáticamente con fórmula (no editar)
A16: VARIABLE INDEPENDIENTE: GESTIÓN DEL CAPITAL DE TRABAJO | S16: VARIABLE DEPENDIENTE: RENTABILIDAD
A17: Año | B17: Inventario saldo anterior | C17: Inventario saldo actual | D17: Inventario PROMEDIO | E17: CxC comerciales saldo anterior | F17: Otras CxC saldo anterior | G17: CxC comerciales saldo actual | H17: Otras CxC saldo actual | I17: CxC totales PROMEDIO | J17: CxP comerciales saldo anterior | K17: CxP comerciales saldo actual | L17: CxP PROMEDIO | M17: Costo de ventas (año) | N17: Ventas netas (año) | O17: PPI (días) | P17: PPC (días) | Q17: PPP (días) | R17: CCE (días) | S17: Utilidad neta (año) | T17: Activo total (cierre) | U17: Patrimonio (cierre) | V17: ROA (%) | W17: ROE (%)
B18: S/000 | C18: S/000 | D18: S/000 | E18: S/000 | F18: S/000 | G18: S/000 | H18: S/000 | I18: S/000 | J18: S/000 | K18: S/000 | L18: S/000 | M18: S/000 | N18: S/000 | S18: S/000 | T18: S/000 | U18: S/000
A19: 2020 | B19: 44353 | C19: 50084 | D19: =AVERAGE(B19,C19) -> 47218.5 | E19: 9622 | F19: 23718 | G19: 12787 | H19: 16688 | I19: =AVERAGE(E19+F19,G19+H19) -> 31407.5 | J19: 70981 | K19: 85609 | L19: =AVERAGE(J19,K19) -> 78295 | M19: 866319 | N19: 1663261 | O19: =IFERROR(D19/M19*360,"-") -> 19.62171 | P19: =IFERROR(I19/N19*360,"-") -> 6.7979109 | Q19: =IFERROR(L19/M19*360,"-") -> 32.53559 | R19: =O19+P19-Q19 -> -6.1159696 | S19: 385559 | T19: 1708321 | U19: 1196378 | V19: =IFERROR(S19/T19,"-") -> 0.2256947 | W19: =IFERROR(S19/U19,"-") -> 0.32227189
A20: 2021 | B20: 50084 | C20: 59856 | D20: =AVERAGE(B20,C20) -> 54970 | E20: 12787 | F20: 16688 | G20: 10183 | H20: 16592 | I20: =AVERAGE(E20+F20,G20+H20) -> 28125 | J20: 85609 | K20: 86042 | L20: =AVERAGE(J20,K20) -> 85825.5 | M20: 1101480 | N20: 2102747 | O20: =IFERROR(D20/M20*360,"-") -> 17.966009 | P20: =IFERROR(I20/N20*360,"-") -> 4.8151299 | Q20: =IFERROR(L20/M20*360,"-") -> 28.050605 | R20: =O20+P20-Q20 -> -5.2694653 | S20: 552792 | T20: 2072248 | U20: 1517920 | V20: =IFERROR(S20/T20,"-") -> 0.26675958 | W20: =IFERROR(S20/U20,"-") -> 0.3641773
A21: 2022 | B21: 59856 | C21: 70544 | D21: =AVERAGE(B21,C21) -> 65200 | E21: 10183 | F21: 16592 | G21: 12630 | H21: 62109 | I21: =AVERAGE(E21+F21,G21+H21) -> 50757 | J21: 86042 | K21: 103394 | L21: =AVERAGE(J21,K21) -> 94718 | M21: 1205403 | N21: 2090683 | O21: =IFERROR(D21/M21*360,"-") -> 19.472326 | P21: =IFERROR(I21/N21*360,"-") -> 8.7399764 | Q21: =IFERROR(L21/M21*360,"-") -> 28.288033 | R21: =O21+P21-Q21 -> -0.075730916 | S21: 407345 | T21: 2100877 | U21: 1594982 | V21: =IFERROR(S21/T21,"-") -> 0.19389284 | W21: =IFERROR(S21/U21,"-") -> 0.2553916
A22: 2023 | B22: 70544 | C22: 68270 | D22: =AVERAGE(B22,C22) -> 69407 | E22: 12630 | F22: 62109 | G22: 14628 | H22: 87810 | I22: =AVERAGE(E22+F22,G22+H22) -> 88588.5 | J22: 103394 | K22: 210432 | L22: =AVERAGE(J22,K22) -> 156913 | M22: 1324474 | N22: 1992610 | O22: =IFERROR(D22/M22*360,"-") -> 18.86524 | P22: =IFERROR(I22/N22*360,"-") -> 16.005069 | Q22: =IFERROR(L22/M22*360,"-") -> 42.649897 | R22: =O22+P22-Q22 -> -7.7795884 | S22: 295664 | T22: 2327495 | U22: 1645610 | V22: =IFERROR(S22/T22,"-") -> 0.12703099 | W22: =IFERROR(S22/U22,"-") -> 0.17966833
A23: 2024 | B23: 68270 | C23: 97619 | D23: =AVERAGE(B23,C23) -> 82944.5 | E23: 14628 | F23: 87810 | G23: 19293 | H23: 104314 | I23: =AVERAGE(E23+F23,G23+H23) -> 113022.5 | J23: 210432 | K23: 221961 | L23: =AVERAGE(J23,K23) -> 216196.5 | M23: 1708130 | N23: 2624541 | O23: =IFERROR(D23/M23*360,"-") -> 17.481117 | P23: =IFERROR(I23/N23*360,"-") -> 15.502939 | Q23: =IFERROR(L23/M23*360,"-") -> 45.564881 | R23: =O23+P23-Q23 -> -12.580825 | S23: 415128 | T23: 2542791 | U23: 1883522 | V23: =IFERROR(S23/T23,"-") -> 0.16325683 | W23: =IFERROR(S23/U23,"-") -> 0.22039987
A24: 2025 | B24: 97619 | C24: 102859 | D24: =AVERAGE(B24,C24) -> 100239 | E24: 19293 | F24: 104314 | G24: 34281 | H24: 83432 | I24: =AVERAGE(E24+F24,G24+H24) -> 120660 | J24: 221961 | K24: 303688 | L24: =AVERAGE(J24,K24) -> 262824.5 | M24: 2104355 | N24: 3474265 | O24: =IFERROR(D24/M24*360,"-") -> 17.148266 | P24: =IFERROR(I24/N24*360,"-") -> 12.502673 | Q24: =IFERROR(L24/M24*360,"-") -> 44.962385 | R24: =O24+P24-Q24 -> -15.311446 | S24: 719907 | T24: 3188844 | U24: 2206979 | V24: =IFERROR(S24/T24,"-") -> 0.22575799 | W24: =IFERROR(S24/U24,"-") -> 0.32619567
A26: Fuente: Estados Financieros Separados Auditados de Compañía Minera Poderosa S.A. (SMV), cifras de cierre de cada ejercicio tal como se reportaron originalmente. Saldos de apertura de 2020 (cierre de 2019): columna 2019 del Estado Separado de Situación Financiera del ejercicio 2020. Los estados de 2023 y 2025 reexpresaron dos saldos comparativos (2022 y 2024); véase la hoja "Verificación EEFF". Archivo base: Poderosa_Estados_Financieros_2020-2025.xlsx.
A28: Fórmulas aplicadas (base 360 días)
A29: PPI = (Inventario promedio / Costo de ventas) x 360
A30: PPC = (Cuentas por cobrar totales promedio [comerciales + otras] / Ventas netas) x 360
A31: PPP = (Cuentas por pagar comerciales promedio / Costo de ventas) x 360
A32: CCE (Ciclo de Conversión de Efectivo) = PPI + PPC - PPP
A33: ROA = Utilidad neta / Activo total (saldo de cierre)
A34: ROE = Utilidad neta / Patrimonio (saldo de cierre)

Sheet Ficha Técnica del Instrumento
A1: FICHA TÉCNICA DEL INSTRUMENTO
A3: Nombre del instrumento | B3: Ficha de registro de datos (ficha de análisis documental)
A4: Técnica asociada | B4: Análisis documental
A5: Autor / marco metodológico | B5: Diseño de investigación: Hernández-Sampieri & Mendoza (2018). Formato de la ficha de registro documental: Ñaupas Paitán et al. (2018) y Valderrama Mendoza (2014). Criterio de cálculo de saldos promedio: Ross, Westerfield & Jordan (2019).
A6: Objetivo | B6: Registrar de forma estructurada los datos contables extraídos de los Estados Financieros Auditados de Compañía Minera Poderosa S.A. (2020-2025) para el cálculo de los indicadores de gestión del capital de trabajo (PPI, PPC, PPP, CCE) y de rentabilidad (ROA, ROE).
A7: Población / unidad de análisis | B7: Estados Financieros Separados Auditados anuales de Compañía Minera Poderosa S.A., periodo 2020-2025
A8: Fuente de los datos | B8: Portal institucional de la Superintendencia del Mercado de Valores (SMV)
A9: Variables que registra | B9: Variable independiente: Gestión del capital de trabajo (PPI, PPC, PPP, CCE) Variable dependiente: Rentabilidad (ROA, ROE)
A10: Criterio de cálculo | B10: Saldo PROMEDIO = (saldo de cierre del año anterior + saldo de cierre del año actual) / 2, base de 360 días. Existe un criterio alternativo de saldo de cierre (sin promediar); se optó por el criterio de saldo promedio por ser el estándar en la literatura de gestión financiera.
A11: Validez | B11: Sin juicio de expertos: el instrumento registra datos secundarios y no es una escala de opinión. Validez de contenido sustentada en (a) indicadores con fórmulas estandarizadas de uso consolidado (Ross et al., 2019; Gitman & Zutter, 2016; Van Horne & Wachowicz, 2010); (b) estructura de la ficha según Ñaupas Paitán et al. (2018) y Valderrama Mendoza (2014); (c) datos tomados de estados financieros auditados y publicados en la SMV; y (d) revisión y aprobación de la ficha por la docente asesora antes del levantamiento de datos.
A12: Confiabilidad | B12: No aplica cálculo de coeficiente (Alfa de Cronbach, KR-20, etc.) al tratarse de datos secundarios de fuente documental oficial (SMV), no de un instrumento de medición psicométrica
A13: Forma de aplicación | B13: Registro manual, un formulario por año/periodo, a partir de la lectura directa del Estado de Situación Financiera y el Estado de Resultados

Sheet Verificación EEFF
A1: VERIFICACIÓN DE LA FICHA CONTRA LOS ESTADOS FINANCIEROS SEPARADOS AUDITADOS
A2: Azul = cifra copiada del estado financiero auditado. Negro = fórmula. "Ficha" toma el valor de la hoja "Ficha de Registro de Datos". Páginas = número de página del archivo PDF. Cifras en S/ miles.
A4: Año | B4: Partida | C4: Ficha | D4: Estado auditado | E4: Diferencia | F4: Estado / página del PDF | G4: Columna usada
A5: 2020 | B5: Inventarios (cierre) | C5: ='Ficha de Registro de Datos'!C19 -> 50084 | D5: 50084 | E5: =C5-D5 -> 0 | F5: Estado de situación financiera, p. 118 de memoria-2020.pdf | G5: 2020 (año corriente)
A6: 2020 | B6: Cuentas por cobrar comerciales (cierre) | C6: ='Ficha de Registro de Datos'!G19 -> 12787 | D6: 12787 | E6: =C6-D6 -> 0 | F6: Estado de situación financiera, p. 118 de memoria-2020.pdf | G6: 2020 (año corriente)
A7: 2020 | B7: Otras cuentas por cobrar (cierre) | C7: ='Ficha de Registro de Datos'!H19 -> 16688 | D7: 16688 | E7: =C7-D7 -> 0 | F7: Estado de situación financiera, p. 118 de memoria-2020.pdf | G7: 2020 (año corriente)
A8: 2020 | B8: Cuentas por pagar comerciales (cierre) | C8: ='Ficha de Registro de Datos'!K19 -> 85609 | D8: 85609 | E8: =C8-D8 -> 0 | F8: Estado de situación financiera, p. 118 de memoria-2020.pdf | G8: 2020 (año corriente)
A9: 2020 | B9: Costo de ventas | C9: ='Ficha de Registro de Datos'!M19 -> 866319 | D9: 866319 | E9: =C9-D9 -> 0 | F9: Estado de resultados, p. 118 de memoria-2020.pdf | G9: 2020 (año corriente)
A10: 2020 | B10: Ingresos de actividades ordinarias | C10: ='Ficha de Registro de Datos'!N19 -> 1663261 | D10: 1663261 | E10: =C10-D10 -> 0 | F10: Estado de resultados, p. 118 de memoria-2020.pdf | G10: 2020 (año corriente)
A11: 2020 | B11: Utilidad neta del período | C11: ='Ficha de Registro de Datos'!S19 -> 385559 | D11: 385559 | E11: =C11-D11 -> 0 | F11: Estado de resultados, p. 118 de memoria-2020.pdf | G11: 2020 (año corriente)
A12: 2020 | B12: Total activo (cierre) | C12: ='Ficha de Registro de Datos'!T19 -> 1708321 | D12: 1708321 | E12: =C12-D12 -> 0 | F12: Estado de situación financiera, p. 118 de memoria-2020.pdf | G12: 2020 (año corriente)
A13: 2020 | B13: Total patrimonio (cierre) | C13: ='Ficha de Registro de Datos'!U19 -> 1196378 | D13: 1196378 | E13: =C13-D13 -> 0 | F13: Estado de situación financiera, p. 118 de memoria-2020.pdf | G13: 2020 (año corriente)
A14: 2021 | B14: Inventarios (cierre) | C14: ='Ficha de Registro de Datos'!C20 -> 59856 | D14: 59856 | E14: =C14-D14 -> 0 | F14: Estado de situación financiera, p. 4 de estados-financieros-2021.pdf | G14: 2021 (año corriente)
A15: 2021 | B15: Cuentas por cobrar comerciales (cierre) | C15: ='Ficha de Registro de Datos'!G20 -> 10183 | D15: 10183 | E15: =C15-D15 -> 0 | F15: Estado de situación financiera, p. 4 de estados-financieros-2021.pdf | G15: 2021 (año corriente)
A16: 2021 | B16: Otras cuentas por cobrar (cierre) | C16: ='Ficha de Registro de Datos'!H20 -> 16592 | D16: 16592 | E16: =C16-D16 -> 0 | F16: Estado de situación financiera, p. 4 de estados-financieros-2021.pdf | G16: 2021 (año corriente)
A17: 2021 | B17: Cuentas por pagar comerciales (cierre) | C17: ='Ficha de Registro de Datos'!K20 -> 86042 | D17: 86042 | E17: =C17-D17 -> 0 | F17: Estado de situación financiera, p. 4 de estados-financieros-2021.pdf | G17: 2021 (año corriente)
A18: 2021 | B18: Costo de ventas | C18: ='Ficha de Registro de Datos'!M20 -> 1101480 | D18: 1101480 | E18: =C18-D18 -> 0 | F18: Estado de resultados, p. 4 de estados-financieros-2021.pdf | G18: 2021 (año corriente)
A19: 2021 | B19: Ingresos de actividades ordinarias | C19: ='Ficha de Registro de Datos'!N20 -> 2102747 | D19: 2102747 | E19: =C19-D19 -> 0 | F19: Estado de resultados, p. 4 de estados-financieros-2021.pdf | G19: 2021 (año corriente)
A20: 2021 | B20: Utilidad neta del período | C20: ='Ficha de Registro de Datos'!S20 -> 552792 | D20: 552792 | E20: =C20-D20 -> 0 | F20: Estado de resultados, p. 4 de estados-financieros-2021.pdf | G20: 2021 (año corriente)
A21: 2021 | B21: Total activo (cierre) | C21: ='Ficha de Registro de Datos'!T20 -> 2072248 | D21: 2072248 | E21: =C21-D21 -> 0 | F21: Estado de situación financiera, p. 4 de estados-financieros-2021.pdf | G21: 2021 (año corriente)
A22: 2021 | B22: Total patrimonio (cierre) | C22: ='Ficha de Registro de Datos'!U20 -> 1517920 | D22: 1517920 | E22: =C22-D22 -> 0 | F22: Estado de situación financiera, p. 4 de estados-financieros-2021.pdf | G22: 2021 (año corriente)
A23: 2022 | B23: Inventarios (cierre) | C23: ='Ficha de Registro de Datos'!C21 -> 70544 | D23: 70544 | E23: =C23-D23 -> 0 | F23: Estado de situación financiera, p. 7 de estados-financieros-2022.pdf | G23: 2022 (año corriente)
A24: 2022 | B24: Cuentas por cobrar comerciales (cierre) | C24: ='Ficha de Registro de Datos'!G21 -> 12630 | D24: 12630 | E24: =C24-D24 -> 0 | F24: Estado de situación financiera, p. 7 de estados-financieros-2022.pdf | G24: 2022 (año corriente)
A25: 2022 | B25: Otras cuentas por cobrar (cierre) | C25: ='Ficha de Registro de Datos'!H21 -> 62109 | D25: 62109 | E25: =C25-D25 -> 0 | F25: Estado de situación financiera, p. 7 de estados-financieros-2022.pdf | G25: 2022 (año corriente)
A26: 2022 | B26: Cuentas por pagar comerciales (cierre) | C26: ='Ficha de Registro de Datos'!K21 -> 103394 | D26: 103394 | E26: =C26-D26 -> 0 | F26: Estado de situación financiera, p. 7 de estados-financieros-2022.pdf | G26: 2022 (año corriente)
A27: 2022 | B27: Costo de ventas | C27: ='Ficha de Registro de Datos'!M21 -> 1205403 | D27: 1205403 | E27: =C27-D27 -> 0 | F27: Estado de resultados, p. 8 de estados-financieros-2022.pdf | G27: 2022 (año corriente)
A28: 2022 | B28: Ingresos de actividades ordinarias | C28: ='Ficha de Registro de Datos'!N21 -> 2090683 | D28: 2090683 | E28: =C28-D28 -> 0 | F28: Estado de resultados, p. 8 de estados-financieros-2022.pdf | G28: 2022 (año corriente)
A29: 2022 | B29: Utilidad neta del período | C29: ='Ficha de Registro de Datos'!S21 -> 407345 | D29: 407345 | E29: =C29-D29 -> 0 | F29: Estado de resultados, p. 8 de estados-financieros-2022.pdf | G29: 2022 (año corriente)
A30: 2022 | B30: Total activo (cierre) | C30: ='Ficha de Registro de Datos'!T21 -> 2100877 | D30: 2100877 | E30: =C30-D30 -> 0 | F30: Estado de situación financiera, p. 7 de estados-financieros-2022.pdf | G30: 2022 (año corriente)
A31: 2022 | B31: Total patrimonio (cierre) | C31: ='Ficha de Registro de Datos'!U21 -> 1594982 | D31: 1594982 | E31: =C31-D31 -> 0 | F31: Estado de situación financiera, p. 7 de estados-financieros-2022.pdf | G31: 2022 (año corriente)
A32: 2023 | B32: Inventarios (cierre) | C32: ='Ficha de Registro de Datos'!C22 -> 68270 | D32: 68270 | E32: =C32-D32 -> 0 | F32: Estado de situación financiera, p. 7 de EEFF_Separados_Auditados_Poderosa_2023.pdf | G32: 2023 (año corriente)
A33: 2023 | B33: Cuentas por cobrar comerciales (cierre) | C33: ='Ficha de Registro de Datos'!G22 -> 14628 | D33: 14628 | E33: =C33-D33 -> 0 | F33: Estado de situación financiera, p. 7 de EEFF_Separados_Auditados_Poderosa_2023.pdf | G33: 2023 (año corriente)
A34: 2023 | B34: Otras cuentas por cobrar (cierre) | C34: ='Ficha de Registro de Datos'!H22 -> 87810 | D34: 87810 | E34: =C34-D34 -> 0 | F34: Estado de situación financiera, p. 7 de EEFF_Separados_Auditados_Poderosa_2023.pdf | G34: 2023 (año corriente)
A35: 2023 | B35: Cuentas por pagar comerciales (cierre) | C35: ='Ficha de Registro de Datos'!K22 -> 210432 | D35: 210432 | E35: =C35-D35 -> 0 | F35: Estado de situación financiera, p. 7 de EEFF_Separados_Auditados_Poderosa_2023.pdf | G35: 2023 (año corriente)
A36: 2023 | B36: Costo de ventas | C36: ='Ficha de Registro de Datos'!M22 -> 1324474 | D36: 1324474 | E36: =C36-D36 -> 0 | F36: Estado de resultados, p. 8 de EEFF_Separados_Auditados_Poderosa_2023.pdf | G36: 2023 (año corriente)
A37: 2023 | B37: Ingresos de actividades ordinarias | C37: ='Ficha de Registro de Datos'!N22 -> 1992610 | D37: 1992610 | E37: =C37-D37 -> 0 | F37: Estado de resultados, p. 8 de EEFF_Separados_Auditados_Poderosa_2023.pdf | G37: 2023 (año corriente)
A38: 2023 | B38: Utilidad neta del período | C38: ='Ficha de Registro de Datos'!S22 -> 295664 | D38: 295664 | E38: =C38-D38 -> 0 | F38: Estado de resultados, p. 8 de EEFF_Separados_Auditados_Poderosa_2023.pdf | G38: 2023 (año corriente)
A39: 2023 | B39: Total activo (cierre) | C39: ='Ficha de Registro de Datos'!T22 -> 2327495 | D39: 2327495 | E39: =C39-D39 -> 0 | F39: Estado de situación financiera, p. 7 de EEFF_Separados_Auditados_Poderosa_2023.pdf | G39: 2023 (año corriente)
A40: 2023 | B40: Total patrimonio (cierre) | C40: ='Ficha de Registro de Datos'!U22 -> 1645610 | D40: 1645610 | E40: =C40-D40 -> 0 | F40: Estado de situación financiera, p. 7 de EEFF_Separados_Auditados_Poderosa_2023.pdf | G40: 2023 (año corriente)
A41: 2024 | B41: Inventarios (cierre) | C41: ='Ficha de Registro de Datos'!C23 -> 97619 | D41: 97619 | E41: =C41-D41 -> 0 | F41: Estado de situación financiera, p. 7 de EEFF_Separados_Auditados_Poderosa_2024.pdf | G41: 2024 (año corriente)
...
